Workbook

Sheet CAP
A1: 问题：首检未按时执行
L2: 负责人
J3: 要求 | K3: 2.1 D→C，需要认证技能
J4: 流程 | K4: 1. 质量部建立规范化认证技能内容（培训内容、如何考核） | L4: Eric | M4: 45273
K5: 2. 生产部 建立技能矩阵显示（朱超、春来、春旭、刘旭、康师傅、炳龙） | L5: Leo | M5: 45275
K6: 3. 生产部 更新首件检验流程文件 First Article Inspection | L6: 炳龙 | M6: 45272
K7: 4. TOP5增加首检负责人的确认环节 | L7: 炳龙 | M7: 45272
A14: 问题：首检有效性不强，未能发现问题
J16: Grvl120 | K16: 竖管方向应该是凸面朝下
K17: 竖管与把立要求应为5-6N.m
K18: 碟刹转接座，前，应无扭力要求
J19: ST530 | K19: 铃铛已取消，首检表上还有？需要确认内外销版本。
K20: 坐垫与坐垫杆（螺母）扭力应该为16-18N.m
A25: 问题3-1：人员技能未达标，但在独立操作。
A47: 问题3-2：人员技能达标，但仍会发现生产动作与SOP不符合
A48: 方向1：员工觉得SOP需要优化，员工提供3OK或金点子反馈 | E48: 领班TOP5提醒员工 | G48: Deadline
A49: 措施： | G49: 45275
A50: 方向2：老员工熟悉SOP，所以没看 | E50: Leo、炳龙、春旭各访谈1名员工
A51: 措施：
A52: 方向3：员工知道标准是SOP，但是操作前或者操作时不看
A53: 措施：
A54: 炳龙：访谈王纯得到反馈如下：
A55: 1、入厂时的被培训方式是口口相传，后来就习惯了；
A56: 2、口口相传和看SOP对比，看相对较慢，也没有口口相传清晰！
A58: Leo: 访谈两名员工，朱超：确实存在有些时候SOP与实际不一致，会有几个阶段，生产提出更新但还未更新的时候必须按照正确的来。基于类似问题，后续必须尽快更新SOP，SOP不准确生产拒绝生产。
A59: 金雪英：备料的SOP执行会有与SOP不符的情况，在小批量工单的时候，没法严格按照工单备料，主要效率会受较大影响。生产会组织梳理类似问题，一方面看如何优化SOP，一方面看如何提升换型效率。
A60: 春旭：访谈一名员工，臧进：每天都看SOP，SOP并没有更改，所以有的时候没看。每天做一个车型，SOP没有改变也就看一遍就结束了。越熟悉越不会看。

Sheet CP Monitor问题记录（2023）
A1: Back | B1: Control Plan Monitor Problem Record 控制计划稽核问题记录 | I1: 问题关闭规则 1.Monitor结束各小组问题记录人登记问题 2.问题负责人写出临时纠正措施，其余人员可提供建议（单发个例问题不用进行原因分析，只填写临时纠正措施） 3.若没有好的措施，请问题负责人自行更新并执行（1WK） 4.若是重复发生问题，需要转DPS小组进行CAP分析，CAP分析后若继续复发，则需要进行DPS分析
B2: 日期 | C2: 车型 | D2: 工位 | E2: 岗位 | F2: 问题记录 | G2: 原因分类 | H2: 严重等级 | I2: 原因 | J2: 改善措施 | K2: 反馈人 | L2: 责任人 | M2: 纠正措施 截止日期（+1WK) | N2: 纠正措施 截止日期（+2WK) | O2: 实际完成时间 | P2: 是否重复发生 | Q2: 状态
B3: 44758 | C3: XC50 | E3: A12-坐垫 | F3: 脚踏包装的SOP代码表所提供的SOP（AR1）方法与实际不一致 | I3: SOP错误 | J3: 修改Sop | K3: 刘维维 | L3: 盛家利 | M3: 44767 | N3: 44777 | Q3: Done
B4: 44758 | C4: XC50 | E4: A12-坐垫 | F4: 脚踏包装的SOP代码表所提供的页码与SOP贴的代码不一致；（代码表中XC50的脚踏包装SOP代码为AR1，页码为第7页，实际第7页尾AR2） | I4: SOP错误 | J4: 修改Sop | K4: 刘维维 | L4: 盛家利 | M4: 44767 | N4: 44777 | Q4: Done
B5: 44758 | C5: XC50 | E5: A16-下车 | F5: 脚踏包装在下车工位包装，但该工位无脚踏包装SOP | I5: SOP错误 | J5: 修改Sop | K5: 罗斌 | L5: 盛家利 | M5: 44767 | N5: 44777 | Q5: Done
B6: 44758 | C6: XC50 | E6: A12-坐垫 | F6: CP中要求的坐垫夹在坐弓上的距离要求与现场SOP的要求不一致 | I6: CP需更新 | J6: 更新XC 50的CP | K6: 刘维维 | L6: Eric | M6: 44774 | N6: 44774 | Q6: Done
B7: 44758 | C7: XC50 | E7: A12-坐垫 | F7: CP中要求的坐垫的角度要求与现场SOP的要求不一致 | I7: CP需更新 | J7: 更新XC 50的CP | K7: 刘维维 | L7: Eric | M7: 44774 | N7: 44774 | Q7: Done
B8: 44758 | C8: XC50 | E8: A12-坐垫 | F8: CP中要求的坐垫附件数量与现场SOP的要求不一致 | I8: CP需更新 | J8: 更新XC 50的CP | K8: 刘维维 | L8: Eric | M8: 44774 | N8: 44774 | Q8: Done
B9: 44764 | C9: XC50 | E9: A4-车把安装 | F9: 横管竖管锁紧顺序未按照要求进行对角锁紧 | I9: 员工认为后续工位会重新松开，可以不锁紧 | J9: 1. 立即培训当时工位负责人 2. 重新培训该工位技能掌握的人 | K9: Eric | L9: 张炳龙 | M9: 44778 | N9: 44774 | Q9: Done | R9: 查阅记录
B10: 44764 | C10: XC50 | E10: A4-车把安装 | F10: 横管竖管间隙不满足上下接缝均匀、平行 | I10: 员工认为后续工位会重新松开，可以不锁紧 | J10: 1. 立即培训当时工位负责人 2. 重新培训该工位技能掌握的人 | K10: Eric | L10: 张炳龙 | M10: 44778 | N10: 44774 | Q10: Done | R10: 查阅记录
B11: 44778 | C11: ST 520 | E11: W8-装小零件 | F11: 员工不知道，螺丝外观-碟刹片锁紧螺丝要有耐落胶 | I11: 临时工技能不够熟练 | J11: 立即培训该工位所有临时工 | K11: Eric | L11: 张炳龙 | M11: 44785 | N11: 44774 | Q11: Done | R11: 查阅记录
B12: 44778 | C12: ST 520 | E12: W8-装小零件 | F12: CP要求的对角锁紧与现场SOP不符合 | I12: CP未进行定期评估 | J12: 更新ST 520的CP | K12: Eric | L12: Eric | M12: 44785 | N12: 44785 | Q12: Done
B13: 44778 | C13: ST 520 | E13: W8-装小零件 | F13: 员工不知道，碟刹片外观-无明显变形破损 | J13: 如何通过Sop进行相关管控——炳龙。家利，Eric一起讨论 | K13: Eric | L13: 张炳龙
B14: 44778 | C14: ST 520 | E14: W8-装小零件 | F14: 快拆位置-工位上Sop不完整 | I14: SOP未及时更新 | J14: 修改Sop | K14: Eric | L14: 盛家利 | M14: 44798 | N14: 44792 | Q14: Done
B15: 44778 | C15: ST 520 | E15: W8-装小零件 | F15: 快拆位置-快拆手柄位置与现场Sop不符合（正确的为前轮在对侧，后轮咋碟刹侧） | I15: CP未更新 | J15: 更新ST 520的CP | K15: Eric | L15: Eric | M15: 44785 | N15: 44785 | Q15: Done
B16: 44778 | C16: ST 520 | E16: W8-装小零件 | F16: 员工没有检查轮组整体外观 | I16: 临时工技能不够熟练 | J16: 产线培训 | K16: Eric | L16: 张炳龙 | M16: 44785 | N16: 44805 | Q16: Done | R16: 查阅记录
B17: 44778 | C17: ST 520 | E17: A9 前变调节 | F17: ST 520无轮胎方向要求，与CP不符合 | I17: CP未更新 | J17: 更新ST 520的CP | K17: Eric | L17: Eric | M17: 44785 | N17: 44785 | Q17: Done
B18: 44778 | C18: ST 520 | E18: A9 前变调节 | F18: 前轮快拆手柄在碟刹侧要求与现场Sop不符合，应为碟刹对侧 | I18: CP未更新 | J18: 更新ST 520的CP | K18: Eric | L18: Eric | M18: 44785 | N18: 44785 | Q18: Done
B19: 44778 | C19: ST 520 | E19: A9 前变调节 | F19: 前刹车线走向-工位并不明确在具体哪一个，会根据限速改变 | I19: 根据不同线速会有相应调整 | J19: 确保涉及工位的员工掌握相应技能 | K19: Eric | L19: 盛家利 | M19: 44785 | N19: 44785 | Q19: Done
B20: 44804 | C20: MTB ST 530 CN 27,5" RED | E20: A7-后轮组装 | F20: 变速线管长度与刹车线管长度 该要求为备料工位，控制点工位应改为备料工位 | I20: 备料工位并入生产管理，控制计划未及时更新 | J20: 在ST 520/530的CP中增加对备料工位的管控 | K20: Eric | L20: Eric | M20: 44813 | N20: 44811 | Q20: Done
B21: 44804 | C21: MTB ST 530 CN 27,5" RED | E21: A7-后轮组装 | F21: 曲柄盖帽安装，ST520/530无需该控制点 | I21: CP未更新 | J21: 更新ST 520/530的CP | K21: Eric | L21: Eric | M21: 44813 | N21: 44811 | Q21: Done
B22: 44810 | C22: ST 520 RR CN FR GREY | E22: A12-坐垫组装 | F22: 上锁片与座弓末端距离20±3mm，未在SOP中 | I22: 要求未与SPEC对应 | J22: 1.更新ST 520/530的CP 2.更新SOP | K22: Eric | L22: 盛家利 | M22: 44813 | N22: 44813 | Q22: Done
B23: 44810 | C23: ST 520 RR CN FR GREY | E23: W2-穿辐条 | F23: 辐条长度要求在SOP中未更新，SOP中是273mm，实际后轮是274和276mm | I23: 辐条铜头mobom后Sop未及时更新 | J23: 更新ST 120/520/530/540的Sop | K23: Eric | L23: 盛家利 | M23: 44813 | N23: 44813 | Q23: Done
B24: 44827 | C24: ST120 | E24: W2-穿辐条 | F24: 后轮辐条规格标准与实际生产的不符合 | I24: 辐条进行切换 CAP分析中---周剑红 | J24: 立即措施：更新辐条长度表 | K24: 罗斌 | L24: 盛家利 | M24: 44865 | N24: 44846 | Q24: Ongoing
B25: 44827 | C25: ST120 | E25: W4-穿辐条 | F25: 衬带安装发现1pcs与标准不符合 | J25: 立即：该工位确认是否有其他不良 | K25: 罗斌 | L25: 张炳龙 | Q25: On going
B26: 44827 | C26: ST120 | E26: W4-辐条锁紧 | F26: 四头锁紧机操作按钮一直在调机状态，并未是生产状态 （也没有找到SOP的相关规定） | J26: 立即：调节设备为生产状态 | K26: 罗斌 | L26: 郑文涛 张炳龙 | Q26: On going
B27: 44827 | C27: ST120 | E27: W4-辐条锁紧 | F27: 缺少四头锁紧机换型时的Sop | J27: 增加换型时四头锁紧机的SOP | K27: 罗斌 | L27: 张炳龙 郑文涛 | Q27: On going
B28: 44827 | C28: ST120 | E28: A7-后轮组装 | F28: 刹车线走线的SOP没有受控，版本信息发布日期与DCC文件不一致 | J28: 更新SOP的版本信息 | K28: Eric | L28: 盛家利 | M28: 44865 | N28: 44853 | Q28: Done
B29: 44869 | C29: Riverside900 | E29: 备料2 | F29: DPR要求增加1mm倒角 | Q29: Done
B30: 44869 | C30: Riverside900 | E30: 备料4 | F30: 线管首件检验表 | Q30: Done
B31: 44869 | C31: Riverside900 | E31: A2-曲柄安装 | F31: 曲柄螺丝不含耐落胶，需要修改CP和SOP | Q31: Done
B32: 44869 | C32: Riverside900 | E32: A2-曲柄安装 | F32: Riverside900与Riverside920s锁紧扭力应改为38-42N.m | Q32: Done
B33: 44869 | C33: Riverside900 | E33: A2-曲柄安装 | F33: 曲柄功能员工50%执行检查曲柄是否有晃点 | J33: 重新培训 | Q33: Done
B34: 44900 | C34: ST520 | E34: BB | F34: Prod-CMW-PRO-ROU-216 Sop中 1.使用的电枪与现场气枪不符合 2.Sop中间隙要求小于0.1mm与控制计划中0.3mm | J34: 修改SOP | K34: Eric、炳龙 | L34: 盛家利 | Q34: Done
B35: 44900 | C35: ST520 | E35: BB | F35: 祖国检查曲柄功能时没有进行左右推拉曲柄检查紧点和晃动 | J35: 培训该工位相关人员 | K35: Eric、炳龙 | L35: 张炳龙 | Q35: Ongoing
B36: 44900 | C36: ST520 | E36: 坐管 | F36: 坐管坐垫锁紧扭力为18-20N.m，与扭力表不符 | J36: 修改相关扭力表 | K36: Eric、炳龙 | L36: 张炳龙 | Q36: Ongoing
B37: 44985 | C37: RC 500 | D37: W5-稳定 | E37: 校正 | F37: 对于张力计使用现场没有SOP进行操作手法确认 | G37: 其他 | I37: 已找到SOP，手法一致 | J37: 无 | K37: Youli/Jianhong | L37: 张炳龙 | O37: 44999 | Q37: Done
B38: 44985 | C38: RC 500 | D38: A9-前变调节 | E38: 变速 | F38: 前变调节工位<链条与前变内侧拨链片之间的间隙为1-3mm>,员工表示是目视检查，不具备检查可行性 | G38: 其他 | J38: 我们没有专业的设备，目前只能靠目视来操作 | K38: Youli/Jianhong | L38: 家利 张炳龙 | M38: 44992 | N38: 44999 | O38: 45007 | Q38: Done
B39: 44985 | C39: RC 500 | D39: A9-前变调节 | E39: 变速 | F39: 前变调节工位SOP要求<转动前变速把，使变把指示到"1"的位置>，与实际操作不符 | G39: SOP | K39: Youli/Jianhong | L39: 盛家利 | M39: 44992 | N39: 44999 | O39: 45007 | Q39: Done
B40: 44985 | C40: RC 500 | D40: A6-三合一 | E40: 三合一 | F40: 车架头管贴美纹胶带未在SOP被规定 | G40: SOP | K40: 罗斌/Eric | L40: 盛家利 张炳龙 | M40: 44992 | N40: 44999 | O40: 45007 | Q40: Done
...

Sheet 审核发现点数据分析（2023）
A1: Back | B1: 控制计划Monitor 结果汇总
B2: 月份 | C2: 备料-线管切割 | D2: W2 | E2: W3 | F2: W4 | G2: W5 | H2: W6 | I2: W7 | J2: W8 | K2: A1 | L2: A2 | M2: A3 | N2: A4 | O2: A5 | P2: A6 | Q2: A7 | R2: A8 | S2: A9 | T2: A10 | U2: A11 | V2: A12 | W2: A13 | X2: A14 | Y2: A15 | Z2: A16 | AA2: A17 | AB2: NOK | AC2: 总工位数 | AD2: 月份 | AE2: 不符合率 | AG2: 月份 | AH2: 备料-线管切割 | AI2: A5-前叉组装 | AJ2: A17-升降坐管
B3: 1月 | C3: NA | D3: NA | E3: NA | F3: NA | G3: NA | H3: NA | I3: NA | J3: NA | K3: OK | L3: NOK | M3: OK | N3: OK | O3: OK | P3: OK | Q3: OK | R3: OK | S3: OK | T3: OK | U3: OK | V3: NOK | W3: NA | X3: NA | Y3: NA | Z3: OK | AA3: NA | AB3: 2 | AC3: 25 | AD3: 1月 | AE3: =AB3/AC3*100% -> 0.08 | AG3: 1月 | AH3: NA | AI3: OK | AJ3: NA
B4: 2月 | C4: NA | D4: NA | E4: OK | F4: NA | G4: OK | H4: OK | I4: OK | J4: OK | K4: OK | L4: OK | M4: OK | N4: OK | O4: OK | P4: NOK | Q4: OK | R4: OK | S4: NOK | T4: OK | U4: NOK | V4: OK | W4: OK | X4: OK | Y4: OK | Z4: NA | AA4: NA | AB4: 4 | AC4: 20 | AD4: 2月 | AE4: =AB4/AC4*100% -> 0.2 | AG4: 2月 | AH4: NA | AI4: OK | AJ4: NA
B5: 3月 | C5: NOK | D5: NOK | E5: OK | F5: OK | G5: OK | H5: OK | I5: OK | J5: NOK | K5: OK | L5: OK | M5: OK | N5: OK | O5: OK | P5: OK | Q5: OK | R5: NOK | S5: OK | T5: OK | U5: OK | V5: NOK | W5: NOK | X5: OK | Y5: OK | Z5: OK | AA5: NOK | AB5: 7 | AC5: 25 | AD5: 3月 | AE5: =AB5/AC5*100% -> 0.28 | AG5: 3月 | AH5: NOK | AI5: OK | AJ5: NOK
B6: 4月 | C6: NOK | D6: OK | E6: OK | F6: OK | G6: OK | H6: OK | I6: NOK | J6: OK | K6: OK | L6: NOK | M6: OK | N6: OK | O6: NOK | P6: OK | Q6: OK | R6: OK | S6: OK | T6: OK | U6: OK | V6: OK | W6: OK | X6: OK | Y6: OK | Z6: OK | AA6: NOK | AB6: 5 | AC6: 25 | AD6: 4月 | AE6: =AB6/AC6*100% -> 0.2 | AG6: 4月 | AH6: NOK | AI6: NOK | AJ6: NOK
B7: 5月 | C7: NOK | D7: OK | E7: OK | F7: OK | G7: NOK | H7: OK | I7: NOK | J7: NOK | K7: NOK | L7: NOK | M7: OK | N7: NOK | O7: NOK | P7: NOK | Q7: OK | R7: OK | S7: OK | T7: OK | U7: NOK | V7: OK | W7: OK | X7: OK | Y7: OK | Z7: NOK | AA7: OK | AB7: 11 | AC7: 25 | AD7: 5月 | AE7: =AB7/AC7*100% -> 0.44 | AG7: 5月 | AH7: NOK | AI7: NOK | AJ7: OK
B8: 6月 | C8: NOK | D8: OK | E8: OK | F8: OK | G8: OK | H8: OK | I8: NOK | J8: NOK | K8: OK | L8: NOK | M8: OK | N8: OK | O8: NOK | P8: OK | Q8: OK | R8: OK | S8: OK | T8: OK | U8: OK | V8: OK | W8: OK | X8: NOK | Y8: OK | Z8: OK | AA8: NOK | AB8: 7 | AC8: 25 | AD8: 6月 | AE8: =AB8/AC8*100% -> 0.28 | AG8: 6月 | AH8: NOK | AI8: NOK | AJ8: NOK
B9: 7月 | C9: NOK | D9: OK | E9: OK | F9: OK | G9: OK | H9: OK | I9: OK | J9: OK | K9: OK | L9: NOK | M9: OK | N9: OK | O9: OK | P9: OK | Q9: OK | R9: OK | S9: OK | T9: OK | U9: OK | V9: OK | W9: OK | X9: OK | Y9: OK | Z9: OK | AA9: OK | AB9: 2 | AC9: 15 | AD9: 7月 | AE9: =AB9/AC9*100% -> 0.13333333 | AG9: 7月 | AH9: NOK | AI9: OK | AJ9: OK
B10: 8月 | C10: NOK | D10: NOK | E10: OK | F10: OK | G10: OK | H10: OK | I10: OK | J10: NOK | K10: OK | L10: OK | M10: NOK | N10: NOK | O10: OK | P10: OK | Q10: NOK | R10: OK | S10: OK | T10: OK | U10: OK | V10: OK | W10: OK | X10: OK | Y10: OK | Z10: OK | AA10: OK | AB10: 5 | AC10: 25 | AD10: 8月 | AE10: =AB10/AC10*100% -> 0.2 | AG10: 8月 | AH10: NOK | AI10: OK | AJ10: OK
B11: 9月 | C11: OK | D11: OK | E11: OK | F11: OK | G11: OK | H11: OK | I11: NOK | K11: OK | L11: OK | M11: OK | N11: OK | O11: OK | P11: OK | Q11: OK | R11: OK | S11: OK | T11: OK | U11: OK | V11: OK | W11: NOK | X11: OK | Y11: OK | Z11: OK | AA11: OK | AB11: 2 | AC11: 20 | AD11: 9月 | AE11: =AB11/AC11*100% -> 0.1 | AG11: 9月 | AH11: OK | AI11: OK | AJ11: OK
B12: 10月 | C12: OK | D12: OK | E12: OK | F12: OK | G12: OK | H12: OK | I12: NOK | J12: NOK | K12: OK | L12: NOK | M12: OK | N12: NOK | O12: OK | P12: OK | Q12: OK | R12: OK | S12: OK | T12: OK | U12: OK | V12: OK | W12: OK | X12: OK | Y12: OK | Z12: OK | AA12: OK | AB12: 4 | AC12: 25 | AD12: 10月 | AE12: =AB12/AC12*100% -> 0.16 | AG12: 10月 | AH12: OK | AI12: OK | AJ12: OK
B13: 11月 | C13: OK | D13: OK | E13: OK | F13: OK | G13: OK | H13: OK | I13: OK | J13: NOK | K13: OK | L13: NOK | M13: OK | N13: OK | O13: OK | P13: OK | Q13: NOK | R13: OK | S13: OK | T13: OK | U13: OK | V13: OK | W13: OK | X13: OK | Y13: OK | Z13: OK | AA13: OK | AB13: 3 | AC13: 25 | AD13: 11月 | AE13: =AB13/AC13*100% -> 0.12 | AG13: 11月 | AH13: OK | AI13: OK | AJ13: OK
B14: 12月 | L14: NOK | M14: NOK | S14: NOK | U14: NOK | AB14: 4 | AC14: 25 | AD14: 12月 | AE14: =AB14/AC14*100% -> 0.16
B15: YTD-NOK | AB15: =sum(AB3:AB14) -> 56 | AC15: =sum(AC3:AC14) -> 280 | AD15: YTD | AE15: =AB15/AC15*100% -> 0.2
C16: 1月 | D16: 2月 | E16: 3月 | F16: 4月 | G16: 5月 | H16: 6月 | I16: 7月 | J16: 8月 | K16: 9月 | L16: 10月 | M16: 11月 | N16: 12月 | P16: 2023年产线工位不符合率 | AG16: =sum(AB3:AB7)/sum(AC3:AC7) -> 0.24166667
B17: 量具 | C17: 1 | D17: 1 | E17: 0 | F17: 1 | G17: 0 | H17: 0 | I17: 1 | J17: 0 | K17: 0 | L17: 0 | M17: 0 | N17: 0 | P17: 控制要求 | Q17: 四月份 | R17: 五月份 | S17: 六月份 | T17: 七月份 | U17: 八月份 | V17: 九月份 | W17: 十月份 | X17: 十一月份 | Y17: 十二月份 | Z17: 总数 | AG17: =sum(AB9:AB13)/sum(AC9:AC13) -> 0.14545455
C18: 1月 | D18: 2月 | E18: 3月 | F18: 4月 | G18: 5月 | H18: 6月 | I18: 7月 | J18: 8月 | K18: 9月 | L18: 10月 | M18: 11月 | N18: 12月 | P18: 工位--NOK | Q18: 6 | R18: 3 | S18: 4 | T18: 3 | U18: 4 | V18: 5 | W18: 3 | X18: 2 | Y18: 4 | Z18: 34
B19: SOP | C19: 5 | D19: 2 | E19: 2 | F19: 1 | G19: 1 | H19: 0 | I19: 3 | J19: 1 | K19: 3 | L19: 0 | M19: 2 | N19: 1 | P19: Monitor的工位总数--All | Q19: 18 | R19: 15 | S19: 10 | T19: 12 | U19: 18 | V19: 21 | W19: 17 | X19: 16 | Y19: 18 | Z19: 145
C20: 1月 | D20: 2月 | E20: 3月 | F20: 4月 | G20: 5月 | H20: 6月 | I20: 7月 | J20: 8月 | K20: 9月 | L20: 10月 | M20: 11月 | N20: 12月 | P20: 控制要求 | Q20: 第一次 | R20: 第二次 | S20: 第三次 | T20: 第四次 | U20: 第五次 | V20: 第六次 | W20: 第七次 | X20: 第八次 | Y20: 第九次 | Z20: 第十次 | AA20: 第十一次 | AB20: 第十二次
B21: 技能 | C21: 6 | D21: 2 | E21: 1 | F21: 2 | G21: 2 | H21: 2 | I21: 2 | J21: 2 | K21: 1 | L21: 3 | M21: 2 | N21: 3 | P21: NCR | Q21: =Q18/(Q19+Q18)*100% -> 0.25 | R21: =R18/R19 -> 0.2 | S21: =S18/S19 -> 0.4 | T21: =T18/T19 -> 0.25 | U21: =U18/U19 -> 0.22222222 | V21: =V18/V19 -> 0.23809524 | W21: =W18/W19 -> 0.17647059 | X21: =X18/X19 -> 0.125 | Y21: =Y18/Y19 -> 0.22222222 | ... AB21: =AB18/AB19 -> #DIV/0!
C22: 1月 | D22: 2月 | E22: 3月 | F22: 4月 | G22: 5月 | H22: 6月 | I22: 7月 | J22: 8月 | K22: 9月 | L22: 10月 | M22: 11月 | N22: 12月
B23: 产品 | C23: 1 | D23: 2 | E23: 0 | F23: 2 | G23: 1 | H23: 2 | I23: 0 | J23: 0 | K23: 0 | L23: 0 | N23: 0

Sheet 审核发现点数据分析（2024）
A1: Back | B1: 控制计划Monitor 结果汇总
B2: 月份 | C2: 备料-线管切割 | D2: W2 | E2: W3 | F2: W4 | G2: W5 | H2: W6 | I2: W7 | J2: W8 | K2: A1 | L2: A2 | M2: A3 | N2: A4 | O2: A5 | P2: A6 | Q2: A7 | R2: A8 | S2: A9 | T2: A10 | U2: A11 | V2: A12 | W2: A13 | X2: A14 | Y2: A15 | Z2: A16 | AA2: A17 | AB2: NOK | AC2: 总工位数 | AD2: 月份 | AE2: 不符合率 | AG2: 月份 | AH2: 备料-线管切割 | AI2: A5-前叉组装 | AJ2: A17-升降坐管
B3: 1月 | G3: NOK | M3: NOK | O3: NOK | P3: NOK | AB3: 4 | AC3: 25 | AD3: 1月 | AE3: =AB3/AC3*100% -> 0.16 | AG3: 1月 | AH3: NA | AI3: OK | AJ3: NA
B4: 2月 | AB4: 0 | AC4: 20 | AD4: 2月 | AE4: =AB4/AC4*100% -> 0 | AG4: 2月 | AH4: NA | AI4: OK | AJ4: NA
B5: 3月 | L5: NOK | M5: NOK | Z5: NOK | AB5: 3 | AC5: 25 | AD5: 3月 | AE5: =AB5/AC5*100% -> 0.12 | AG5: 3月 | AH5: NOK | AI5: OK | AJ5: NOK
B6: 4月 | C6: NOK | AB6: 1 | AC6: 25 | AD6: 4月 | AE6: =AB6/AC6*100% -> 0.04 | AG6: 4月 | AH6: NOK | AI6: NOK | AJ6: NOK
B7: 5月 | D7: NOK | AA7: NOK | AB7: 2 | AC7: 25 | AD7: 5月 | AE7: =AB7/AC7*100% -> 0.08 | AG7: 5月 | AH7: NOK | AI7: NOK | AJ7: OK
B8: 6月 | AB8: 5 | AC8: 25 | AD8: 6月 | AE8: =AB8/AC8*100% -> 0.2 | AG8: 6月 | AH8: NOK | AI8: NOK | AJ8: NOK
B9: 7月 | AB9: 3 | AC9: 25 | AD9: 7月 | AE9: =AB9/AC9*100% -> 0.12 | AG9: 7月 | AH9: NOK | AI9: OK | AJ9: OK
B10: 8月 | AB10: 6 | AC10: 25 | AD10: 8月 | AE10: =AB10/AC10*100% -> 0.24 | AG10: 8月 | AH10: NOK | AI10: OK | AJ10: OK
B11: 9月 | AB11: 4 | AC11: 25 | AD11: 9月 | AE11: =AB11/AC11*100% -> 0.16 | AG11: 9月 | AH11: OK | AI11: OK | AJ11: OK
B12: 10月 | AB12: 1 | AC12: 25 | AD12: 10月 | AE12: =AB12/AC12*100% -> 0.04 | AG12: 10月 | AH12: OK | AI12: OK | AJ12: OK
B13: 11月 | AB13: 0 | AC13: 25 | AD13: 11月 | AE13: =AB13/AC13*100% -> 0 | AG13: 11月 | AH13: OK | AI13: OK | AJ13: OK
B14: 12月 | AB14: 2 | AC14: 25 | AD14: 12月 | AE14: =AB14/AC14*100% -> 0.08
B15: YTD-NOK | AB15: =sum(AB3:AB14) -> 31 | AC15: =sum(AC3:AC14) -> 295 | AD15: YTD | AE15: =AB15/AC15*100% -> 0.10508475
C16: 1月 | D16: 2月 | E16: 3月 | F16: 4月 | G16: 5月 | H16: 6月 | I16: 7月 | J16: 8月 | K16: 9月 | L16: 10月 | M16: 11月 | N16: 12月 | P16: 2024年产线工位不符合率 | AG16: =sum(AB3:AB7)/sum(AC3:AC7) -> 0.083333333
B17: 量具 | P17: 控制要求 | Q17: 四月份 | R17: 五月份 | S17: 六月份 | T17: 七月份 | U17: 八月份 | V17: 九月份 | W17: 十月份 | X17: 十一月份 | Y17: 十二月份 | Z17: 总数 | AG17: =sum(AB9:AB13)/sum(AC9:AC13) -> 0.112
C18: 1月 | D18: 2月 | E18: 3月 | F18: 4月 | G18: 5月 | H18: 6月 | I18: 7月 | J18: 8月 | K18: 9月 | L18: 10月 | M18: 11月 | N18: 12月 | P18: 工位--NOK | Q18: 6 | R18: 3 | S18: 4 | T18: 3 | U18: 4 | V18: 5 | W18: 3 | X18: 2 | Y18: 4 | Z18: 34
B19: SOP | P19: Monitor的工位总数--All | Q19: 18 | R19: 15 | S19: 10 | T19: 12 | U19: 18 | V19: 21 | W19: 17 | X19: 16 | Y19: 18 | Z19: 145
C20: 1月 | D20: 2月 | E20: 3月 | F20: 4月 | G20: 5月 | H20: 6月 | I20: 7月 | J20: 8月 | K20: 9月 | L20: 10月 | M20: 11月 | N20: 12月 | P20: 控制要求 | Q20: 第一次 | R20: 第二次 | S20: 第三次 | T20: 第四次 | U20: 第五次 | V20: 第六次 | W20: 第七次 | X20: 第八次 | Y20: 第九次 | Z20: 第十次 | AA20: 第十一次 | AB20: 第十二次
B21: 技能 | P21: NCR | Q21: =Q18/(Q19+Q18)*100% -> 0.25 | R21: =R18/R19 -> 0.2 | S21: =S18/S19 -> 0.4 | T21: =T18/T19 -> 0.25 | U21: =U18/U19 -> 0.22222222 | V21: =V18/V19 -> 0.23809524 | W21: =W18/W19 -> 0.17647059 | X21: =X18/X19 -> 0.125 | Y21: =Y18/Y19 -> 0.22222222 | ... AB21: =AB18/AB19 -> #DIV/0!
C22: 1月 | D22: 2月 | E22: 3月 | F22: 4月 | G22: 5月 | H22: 6月 | I22: 7月 | J22: 8月 | K22: 9月 | L22: 10月 | M22: 11月 | N22: 12月
B23: 产品

Sheet KPI（2023）
A1: Back | B1: 2023 Quality KPI 总览 | I1: FQC拒收率 | J1: 拒收数量/总生产数量 | K1: ≤12000ppm
A2: 客诉DPPM | I2: NCR不良率 | J2: （CP control NOK + CP control DER）/Total number of CP performed | K2: ≤15%
A3: FQC | I3: DPPM | J3: （客户投诉数量*百万）/出货总数量 | K3: ≤3200PPM
A4: PQC
A5: CP Monitor
A6: Routine Pareto analysis

Sheet KPI（2024）
A1: Back | B1: CMW Quality KPI 总览 | I1: FQC拒收率 | J1: 拒收数量/总生产数量 | K1: ≤12000ppm
A2: 客诉DPPM | I2: NCR不良率 | J2: （CP control NOK + CP control DER）/Total number of CP performed | K2: ≤15%
A3: FQC | I3: DPPM | J3: （客户投诉数量*百万）/出货总数量 | K3: ≤3200PPM
A4: PQC
A5: CP Monitor

Sheet KPI（2023）（修改版）
A1: Back | B1: 2023 Quality KPI Dashboard | I1: FQC拒收率 | J1: 拒收数量/总生产数量 | K1: ≤12000ppm
A2: 客诉DPPM | I2: NCR不良率 | J2: （CP control NOK + CP control DER）/Total number of CP performed | K2: ≤15%
A3: FQC | I3: DPPM | J3: （客户投诉数量*百万）/出货总数量 | K3: ≤3200PPM
A4: PQC
A5: CP Monitor
A6: Routine Pareto analysis

Sheet 审核发现点数据分析-小线（2025）
A1: Back | B1: 控制计划Monitor 结果汇总（高端线）
B2: 月份 | C2: 备料-线管切割 | D2: W2 | E2: W3 | F2: W4 | G2: W5 | H2: W6 | I2: W7 | J2: W8 | K2: A1 | L2: A2 | M2: A3 | N2: A4 | O2: A5 | P2: A6 | Q2: A7 | R2: A8 | S2: A9 | T2: A10 | U2: A11 | V2: A12 | W2: A13 | X2: A14 | Y2: A15 | Z2: A16 | AA2: A17 | AB2: NOK | AC2: 总工位数 | AD2: 月份 | AE2: 不符合率 | AG2: 月份 | AH2: 备料-线管切割 | AI2: A5-前叉组装 | AJ2: A17-升降坐管
B3: 1月 | AC3: 25 | AD3: 1月 | AE3: =AB3/AC3*100 -> 0 | AG3: 1月
B4: 2月 | AC4: 20 | AD4: 2月 | AE4: =AB4/AC4*100% -> 0 | AG4: 2月
B5: 3月 | AC5: 25 | AD5: 3月 | AE5: =AB5/AC5*100% -> 0 | AG5: 3月
B6: 4月 | AC6: 25 | AD6: 4月 | AE6: =AB6/AC6*100% -> 0 | AG6: 4月
B7: 5月 | AC7: 25 | AD7: 5月 | AE7: =AB7/AC7*100% -> 0 | AG7: 5月
B8: 6月 | AC8: 25 | AD8: 6月 | AE8: =AB8/AC8*100% -> 0 | AG8: 6月
B9: 7月 | AC9: 25 | AD9: 7月 | AE9: =AB9/AC9*100% -> 0 | AG9: 7月
B10: 8月 | AC10: 25 | AD10: 8月 | AE10: =AB10/AC10*100% -> 0 | AG10: 8月
B11: 9月 | AC11: 25 | AD11: 9月 | AE11: =AB11/AC11*100% -> 0 | AG11: 9月
B12: 10月 | AC12: 25 | AD12: 10月 | AE12: =AB12/AC12*100% -> 0 | AG12: 10月
B13: 11月 | AC13: 25 | AD13: 11月 | AE13: =AB13/AC13*100% -> 0 | AG13: 11月
B14: 12月 | AC14: 25 | AD14: 12月 | AE14: =AB14/AC14*100% -> 0
B15: YTD-NOK | AB15: =sum(AB3:AB14) -> 0 | AC15: =sum(AC3:AC14) -> 295 | AD15: YTD | AE15: =AB15/AC15*100% -> 0
C16: 1月 | D16: 2月 | E16: 3月 | F16: 4月 | G16: 5月 | H16: 6月 | I16: 7月 | J16: 8月 | K16: 9月 | L16: 10月 | M16: 11月 | N16: 12月 | P16: 2025年产线工位不符合率 | AG16: =sum(AB3:AB7)/sum(AC3:AC7) -> 0
B17: 量具 | P17: 控制要求 | Q17: 四月份 | R17: 五月份 | S17: 六月份 | T17: 七月份 | U17: 八月份 | V17: 九月份 | W17: 十月份 | X17: 十一月份 | Y17: 十二月份 | Z17: 总数 | AG17: =sum(AB9:AB13)/sum(AC9:AC13) -> 0
C18: 1月 | D18: 2月 | E18: 3月 | F18: 4月 | G18: 5月 | H18: 6月 | I18: 7月 | J18: 8月 | K18: 9月 | L18: 10月 | M18: 11月 | N18: 12月 | P18: 工位--NOK
B19: SOP | P19: Monitor的工位总数--All
C20: 1月 | D20: 2月 | E20: 3月 | F20: 4月 | G20: 5月 | H20: 6月 | I20: 7月 | J20: 8月 | K20: 9月 | L20: 10月 | M20: 11月 | N20: 12月 | P20: 控制要求 | Q20: 第一次 | R20: 第二次 | S20: 第三次 | T20: 第四次 | U20: 第五次 | V20: 第六次 | W20: 第七次 | X20: 第八次 | Y20: 第九次 | Z20: 第十次 | AA20: 第十一次 | AB20: 第十二次
B21: 技能 | P21: NCR | Q21: =Q18/(Q19+Q18)*100% -> #DIV/0! | R21: =R18/R19 -> #DIV/0! | S21: =S18/S19 -> #DIV/0! | T21: =T18/T19 -> #DIV/0! | U21: =U18/U19 -> #DIV/0! | V21: =V18/V19 -> #DIV/0! | W21: =W18/W19 -> #DIV/0! | X21: =X18/X19 -> #DIV/0! | Y21: =Y18/Y19 -> #DIV/0! | ... AB21: =AB18/AB19 -> #DIV/0!
C22: 1月 | D22: 2月 | E22: 3月 | F22: 4月 | G22: 5月 | H22: 6月 | I22: 7月 | J22: 8月 | K22: 9月 | L22: 10月 | M22: 11月 | N22: 12月
B23: 产品

Sheet 审核发现点数据分析-大线（2025）
A1: Back | B1: 控制计划Monitor 结果汇总（大线）
B2: 月份 | C2: 备料-线管切割 | D2: W2 | E2: W3 | F2: W4 | G2: W5 | H2: W6 | I2: W7 | J2: W8 | K2: A1 | L2: A2 | M2: A3 | N2: A4 | O2: A5 | P2: A6 | Q2: A7 | R2: A8 | S2: A9 | T2: A10 | U2: A11 | V2: A12 | W2: A13 | X2: A14 | Y2: A15 | Z2: A16 | AA2: A17 | AB2: NOK | AC2: 总工位数 | AD2: 月份 | AE2: 不符合率 | AG2: 月份 | AH2: 备料-线管切割 | AI2: A5-前叉组装 | AJ2: A17-升降坐管
B3: 1月 | AB3: 0 | AC3: 25 | AD3: 1月 | AE3: =AB3/AC3*100 -> 0 | AG3: 1月
B4: 2月 | C4: NOK | J4: NOK | L4: NOK | AB4: 3 | AC4: 20 | AD4: 2月 | AE4: =AB4/AC4*100% -> 0.15 | AG4: 2月
B5: 3月 | J5: NOK | V5: NOK | AB5: 2 | AC5: 25 | AD5: 3月 | AE5: =AB5/AC5*100% -> 0.08 | AG5: 3月
B6: 4月 | K6: NOK | L6: NOK | P6: NOK | AB6: 3 | AC6: 19 | AD6: 4月 | AE6: =AB6/AC6*100% -> 0.15789474 | AG6: 4月
B7: 5月 | C7: NOK | O7: NOK | Q7: NOK | AB7: 2 | AC7: 25 | AD7: 5月 | AE7: =AB7/AC7*100% -> 0.08 | AG7: 5月
B8: 6月 | L8: NOK*2 | N8: NOK*2 | Q8: NOK | R8: NOK | V8: NOK | X8: NOK | Y8: NOK | AB8: 9 | AC8: 25 | AD8: 6月 | AE8: =AB8/AC8*100% -> 0.36 | AG8: 6月
B9: 7月 | N9: NOK*2 | AB9: 2 | AC9: 25 | AD9: 7月 | AE9: =AB9/AC9*100% -> 0.08 | AG9: 7月
B10: 8月 | J10: NOK | S10: NOK*2 | AB10: 3 | AC10: 25 | AD10: 8月 | AE10: =AB10/AC10*100% -> 0.12 | AG10: 8月
B11: 9月 | T11: NOK | AB11: 1 | AC11: 25 | AD11: 9月 | AE11: =AB11/AC11*100% -> 0.04 | AG11: 9月
B12: 10月 | AB12: 0 | AC12: 0 | AD12: 10月 | AE12: 0%% | AG12: 10月
B13: 11月 | AB13: 0 | AC13: 0 | AD13: 11月 | AE13: 0%% | AG13: 11月
B14: 12月 | AB14: 0 | AC14: 0 | AD14: 12月 | AE14: =AB14/AC14*100% -> #DIV/0!
B15: YTD-NOK | AB15: =sum(AB3:AB14) -> 25 | AC15: =sum(AC3:AC14) -> 214 | AD15: YTD | AE15: =AB15/AC15*100% -> 0.11682243
C16: 1月 | D16: 2月 | E16: 3月 | F16: 4月 | G16: 5月 | H16: 6月 | I16: 7月 | J16: 8月 | K16: 9月 | L16: 10月 | M16: 11月 | N16: 12月 | P16: 2025年产线工位不符合率 | AG16: =sum(AB3:AB7)/sum(AC3:AC7) -> 0.087719298
B17: 设备 | F17: 1 | P17: 控制要求 | Q17: 四月份 | R17: 五月份 | S17: 六月份 | T17: 七月份 | U17: 八月份 | V17: 九月份 | W17: 十月份 | X17: 十一月份 | Y17: 十二月份 | Z17: 总数 | AG17: =sum(AB9:AB13)/sum(AC9:AC13) -> 0.08
C18: 1月 | D18: 2月 | E18: 3月 | F18: 4月 | G18: 5月 | H18: 6月 | I18: 7月 | J18: 8月 | K18: 9月 | L18: 10月 | M18: 11月 | N18: 12月 | P18: 工位--NOK | Q18: 3 | R18: 2 | S18: 9 | T18: 2 | U18: 3 | V18: 1 | W18: 0 | X18: 0
B19: SOP | D19: 1 | E19: 1 | H19: 4 | P19: Monitor的工位总数--All | Q19: 16 | R19: 25 | S19: 25 | T19: 25 | U19: 25 | V19: 25 | W19: 0 | X19: 0 | AD19: =8/43 -> 0.18604651
C20: 1月 | D20: 2月 | E20: 3月 | F20: 4月 | G20: 5月 | H20: 6月 | I20: 7月 | J20: 8月 | K20: 9月 | L20: 10月 | M20: 11月 | N20: 12月 | P20: 控制要求 | Q20: 第一次 | R20: 第二次 | S20: 第三次 | T20: 第四次 | U20: 第五次 | V20: 第六次 | W20: 第七次 | X20: 第八次 | Y20: 第九次 | Z20: 第十次 | AA20: 第十一次 | AB20: 第十二次
B21: 人员操作 | D21: 1 | E21: 2 | F21: 2 | H21: 2 | I21: 2 | P21: NCR | Q21: =Q18/(Q19+Q18)*100% -> 0.15789474 | R21: =R18/R19 -> 0.08 | S21: =S18/S19 -> 0.36 | T21: =T18/T19 -> 0.08 | U21: =U18/U19 -> 0.12 | V21: =V18/V19 -> 0.04 | W21: 0 | X21: 0 | Y21: =Y18/Y19 -> #DIV/0! | Z21: =Z18/Z19 -> #DIV/0! | AA21: =AA18/AA19 -> #DIV/0! | AB21: =AB18/AB19 -> #DIV/0!
C22: 1月 | D22: 2月 | E22: 3月 | F22: 4月 | G22: 5月 | H22: 6月 | I22: 7月 | J22: 8月 | K22: 9月 | L22: 10月 | M22: 11月 | N22: 12月
B23: 其他 | D23: 1 | G23: 2 | H23: 3
N44: 人员操作 | O44: 9 | P44: =O44/sum($O$44:$O$47) -> 0.40909091
N45: SOP | O45: 6 | P45: =(O44+O45)/$S$45 -> 0.68181818 | S45: =sum(O44:O47) -> 22
N46: 其他 | O46: 6 | P46: =(O45+O46+O44)/$S$45 -> 0.95454545
N47: 设备 | O47: 1 | P47: =(O46+O47+O45+O44)/$S$45 -> 1
A66: 备料-线管切割 | B66: W2 | C66: W3 | D66: W4 | E66: W5 | F66: W6 | G66: W7 | H66: W8 | I66: A1 | J66: A2 | K66: A3 | L66: A4 | M66: A5 | N66: A6 | O66: A7 | P66: A8 | Q66: A9 | R66: A10 | S66: A11 | T66: A12 | U66: A13 | V66: A14 | W66: A15 | X66: A16 | Y66: A17
A67: 2 | H67: 2 | I67: 1 | J67: 4 | L67: 4 | N67: 1 | O67: 2 | P67: 1 | T67: 2 | V67: 1

Sheet 2024 KPI-大小线（IV)
C1: 2024 IV DPPM-大小线
C2: 月份 | D2: 1月 | E2: 2月 | F2: 3月 | G2: 4月 | H2: 5月 | I2: 6月 | J2: 7月 | K2: 8月 | L2: 9月 | M2: 10月 | N2: 11月 | O2: 12月 | P2: YTD
A3: Intern voice Qty | B3: 大线 | C3: KID CYCLING | P3: =SUM(D3:O3) -> 0
C4: 山地ST | D4: 3 | E4: 2 | F4: 4 | G4: 5 | H4: 4 | I4: 5 | J4: 2 | K4: 4 | L4: 5 | M4: 1 | N4: 5 | P4: =SUM(D4:O4) -> 40
C5: 山地XC/AM/Race | F5: 2 | I5: 1 | J5: 3 | K5: 1 | M5: 2 | N5: 2 | P5: =SUM(D5:O5) -> 11
C6: Hybrid Bike | H6: 1 | I6: 2 | L6: 1 | N6: 1 | P6: =SUM(D6:O6) -> 5
C7: 公路RC | E7: 1 | F7: 3 | G7: 2 | I7: 6 | J7: 8 | K7: 9 | L7: 4 | M7: 4 | N7: 1 | P7: =SUM(D7:O7) -> 38
C8: 大线GRVL | F8: 1 | H8: 3 | L8: 1 | M8: 1 | N8: 1 | P8: =SUM(D8:O8) -> 7
C9: 大线EDR | G9: 1 | J9: 1 | M9: 1 | P9: =SUM(D9:O9) -> 3
C10: Total | D10: =SUM(D3:D9) -> 3 | E10: =SUM(E3:E9) -> 3 | F10: =SUM(F3:F9) -> 10 | G10: =SUM(G3:G9) -> 8 | H10: =SUM(H3:H9) -> 8 | I10: =SUM(I3:I9) -> 14 | J10: =SUM(J3:J9) -> 14 | K10: =SUM(K3:K9) -> 14 | ... N10: =SUM(N3:N9) -> 10 | O10: 12 | P10: =SUM(P3:P9) -> 104
B11: 小线 | C11: 小线GRVL | P11: =SUM(D11:O11) -> 0
C12: 小线EDR | F12: 1 | H12: 1 | K12: 1 | L12: 2 | M12: 1 | P12: =SUM(D12:O12) -> 6
C13: 小线RCR | M13: 2 | N13: 3 | P13: =SUM(D13:O13) -> 5
C14: Touring | G14: 2 | H14: 1 | P14: =SUM(D14:O14) -> 3
C15: 小线XC | I15: 2 | P15: =SUM(D15:O15) -> 2
C16: Total | D16: =SUM(D11:D14) -> 0 | E16: =SUM(E11:E14) -> 0 | F16: =SUM(F11:F14) -> 1 | G16: =SUM(G11:G14) -> 2 | H16: =SUM(H11:H14) -> 2 | I16: =SUM(I11:I15) -> 2 | J16: =SUM(J11:J14) -> 0 | K16: =SUM(K11:K14) -> 1 | L16: =SUM(L11:L14) -> 2 | M16: =SUM(M11:M14) -> 3 | N16: =SUM(N11:N14) -> 3 | O16: 1 | P16: =SUM(P11:P14) -> 14
C17: 工厂Total | D17: =SUM(D3:D9,D11:D15) -> 3 | E17: =SUM(E3:E9,E11:E15) -> 3 | F17: =SUM(F3:F9,F11:F15) -> 11 | G17: =SUM(G3:G9,G11:G15) -> 10 | H17: =SUM(H3:H9,H11:H15) -> 10 | I17: =SUM(I3:I9,I11:I15) -> 16 | J17: =SUM(J3:J9,J11:J15) -> 14 | K17: =SUM(K3:K9,K11:K15) -> 15 | ... N17: =SUM(N3:N9,N11:N15) -> 13 | O17: 13 | P17: =SUM(P3:P9,P11:P15) -> 120
A18: Ship out number | B18: 大线 | C18: KID CYCLING | D18: 24 | K18: 72 | L18: 96 | M18: 120 | N18: 48 | P18: =SUM(D18:O18) -> 360
C19: 山地ST | D19: 1620 | E19: 2156 | F19: 2815 | G19: 3140 | H19: 4954 | I19: 3221 | J19: 3241 | K19: 4695 | L19: 2669 | M19: 377 | N19: 754 | O19: 509 | P19: =SUM(D19:O19) -> 30151
C20: 山地XC/AM/Race | D20: 12 | E20: 16 | F20: 8 | G20: 40 | H20: 22 | I20: 87 | J20: 8 | K20: 20 | L20: 59 | M20: 27 | N20: 69 | O20: 7 | P20: =SUM(D20:O20) -> 375
C21: Hybrid Bike | D21: 90 | E21: 16 | F21: 80 | I21: 80 | K21: 68 | L21: 112 | M21: 136 | N21: 15 | P21: =SUM(D21:O21) -> 597
C22: 公路RC | D22: 1321 | E22: 1341 | F22: 237 | G22: 879 | H22: 2539 | I22: 386 | J22: 211 | K22: 640 | L22: 658 | M22: 504 | N22: 2 | O22: 289 | P22: =SUM(D22:O22) -> 9007
C23: 大线GRVL | D23: 0 | E23: 131 | F23: 43 | G23: 175 | H23: 195 | I23: 326 | J23: 229 | K23: 166 | N23: 3 | O23: 318 | P23: =SUM(D23:O23) -> 1586
C24: 大线EDR | D24: 668 | E24: 353 | F24: 538 | G24: 752 | I24: 1595 | J24: 769 | K24: 363 | L24: 1089 | M24: 332 | P24: =SUM(D24:O24) -> 6459
C25: Total | D25: =SUM(D18:D24) -> 3735 | E25: =SUM(E18:E24) -> 4013 | F25: =SUM(F18:F24) -> 3721 | G25: =SUM(G18:G24) -> 4986 | H25: =SUM(H18:H24) -> 7710 | I25: =SUM(I18:I24) -> 5695 | J25: =SUM(J18:J24) -> 4458 | K25: =SUM(K18:K24) -> 6024 | ... P25: =SUM(P18:P24) -> 48535
B26: 小线 | C26: 小线GRVL | D26: 132 | E26: 63 | F26: 197 | G26: 307 | H26: 86 | I26: 203 | J26: 261 | K26: 224 | L26: 47 | P26: =SUM(D26:O26) -> 1520
C27: 小线EDR | D27: 164 | E27: 246 | F27: 138 | G27: 292 | H27: 645 | I27: 111 | J27: 119 | K27: 28 | L27: 251 | M27: 78 | O27: 1 | P27: =SUM(D27:O27) -> 2073
C28: 小线RCR | D28: 0 | E28: 89 | F28: 17 | G28: 86 | H28: 151 | I28: 106 | J28: 176 | K28: 221 | L28: 261 | M28: 231 | N28: 121 | O28: 39 | P28: =SUM(D28:O28) -> 1498
C29: Touring | E29: 47 | G29: 50 | K29: 54 | L29: 19 | P29: =SUM(D29:O29) -> 170
C30: 小线XC | G30: 4 | H30: 54 | J30: 9 | K30: 47 | L30: 58 | M30: 4 | N30: 57 | O30: 16 | P30: =SUM(D30:O30) -> 249
C31: Total | D31: =SUM(D26:D30) -> 296 | E31: =SUM(E26:E30) -> 445 | F31: =SUM(F26:F30) -> 352 | G31: =SUM(G26:G30) -> 739 | H31: =SUM(H26:H30) -> 936 | I31: =SUM(I26:I30) -> 420 | J31: =SUM(J26:J30) -> 565 | K31: =SUM(K26:K30) -> 574 | ... P31: =SUM(P26:P30) -> 5510
C32: 工厂Total | D32: =sum(D18:D24,D26:D30) -> 4031 | E32: =sum(E18:E24,E26:E30) -> 4458 | F32: =sum(F18:F24,F26:F30) -> 4073 | G32: =sum(G18:G24,G26:G30) -> 5725 | H32: =sum(H18:H24,H26:H30) -> 8646 | I32: =sum(I18:I24,I26:I30) -> 6115 | J32: =sum(J18:J24,J26:J30) -> 5023 | K32: =sum(K18:K24,K26:K30) -> 6598 | ... O32: =sum(O18:O24,O26:O30) -> 1179 | P32: =SUM(P18:P24,P26:P30) -> 54045
A33: DPPM | B33: 大线 | C33: KID CYCLING | D33: =(D3/D18)*1000000 -> 0 | E33: =(E3/E18)*1000000 -> #DIV/0! | F33: =(F3/F18)*1000000 -> #DIV/0! | G33: =(G3/G18)*1000000 -> #DIV/0! | H33: =(H3/H18)*1000000 -> #DIV/0! | I33: =(I3/I18)*1000000 -> #DIV/0! | J33: =(J3/J18)*1000000 -> #DIV/0! | K33: =(K3/K18)*1000000 -> 0 | ... P33: =(P3/P18)*1000000 -> 0
C34: 山地ST | D34: =(D4/D19)*1000000 -> 1851.8519 | E34: =(E4/E19)*1000000 -> 927.64378 | F34: =(F4/F19)*1000000 -> 1420.9591 | G34: =(G4/G19)*1000000 -> 1592.3567 | H34: =(H4/H19)*1000000 -> 807.42834 | I34: =(I4/I19)*1000000 -> 1552.3129 | J34: =(J4/J19)*1000000 -> 617.09349 | K34: =(K4/K19)*1000000 -> 851.97018 | ... P34: =(P4/P19)*1000000 -> 1326.6558
C35: 山地XC/AM/Race | D35: =(D5/D20)*1000000 -> 0 | E35: =(E5/E20)*1000000 -> 0 | F35: =(F5/F20)*1000000 -> 250000 | G35: =(G5/G20)*1000000 -> 0 | H35: =(H5/H20)*1000000 -> 0 | I35: =(I5/I20)*1000000 -> 11494.253 | J35: =(J5/J20)*1000000 -> 375000 | K35: =(K5/K20)*1000000 -> 50000 | ... P35: =(P5/P20)*1000000 -> 29333.333
C36: Hybrid Bike | D36: =(D6/D21)*1000000 -> 0 | E36: =(E6/E21)*1000000 -> 0 | F36: =(F6/F21)*1000000 -> 0 | G36: =(G6/G21)*1000000 -> #DIV/0! | H36: =(H6/H21)*1000000 -> #DIV/0! | I36: =(I6/I21)*1000000 -> 25000 | J36: =(J6/J21)*1000000 -> #DIV/0! | K36: =(K6/K21)*1000000 -> 0 | ... P36: =(P6/P21)*1000000 -> 8375.2094
C37: 公路RC | D37: =(D7/D22)*1000000 -> 0 | E37: =(E7/E22)*1000000 -> 745.71216 | F37: =(F7/F22)*1000000 -> 12658.228 | G37: =(G7/G22)*1000000 -> 2275.3129 | H37: =(H7/H22)*1000000 -> 0 | I37: =(I7/I22)*1000000 -> 15544.041 | J37: =(J7/J22)*1000000 -> 37914.692 | K37: =(K7/K22)*1000000 -> 14062.5 | ... P37: =(P7/P22)*1000000 -> 4218.9408
C38: 大线GRVL | D38: =(D8/D23)*1000000 -> #DIV/0! | E38: =(E8/E23)*1000000 -> 0 | F38: =(F8/F23)*1000000 -> 23255.814 | G38: =(G8/G23)*1000000 -> 0 | H38: =(H8/H23)*1000000 -> 15384.615 | I38: =(I8/I23)*1000000 -> 0 | J38: =(J8/J23)*1000000 -> 0 | K38: =(K8/K23)*1000000 -> 0 | ... P38: =(P8/P23)*1000000 -> 4413.6192
C39: 大线EDR | D39: =(D9/D24)*1000000 -> 0 | E39: =(E9/E24)*1000000 -> 0 | F39: =(F9/F24)*1000000 -> 0 | G39: =(G9/G24)*1000000 -> 1329.7872 | H39: =(H9/H24)*1000000 -> #DIV/0! | I39: =(I9/I24)*1000000 -> 0 | J39: =(J9/J24)*1000000 -> 1300.3901 | K39: =(K9/K24)*1000000 -> 0 | ... P39: =(P9/P24)*1000000 -> 464.46818
C40: 大线Total | D40: =(D10/D25)*1000000 -> 803.21285 | E40: =(E10/E25)*1000000 -> 747.5704 | F40: =(F10/F25)*1000000 -> 2687.4496 | G40: =(G10/G25)*1000000 -> 1604.4926 | H40: =(H10/H25)*1000000 -> 1037.6135 | I40: =(I10/I25)*1000000 -> 2458.2968 | J40: =(J10/J25)*1000000 -> 3140.4217 | K40: =(K10/K25)*1000000 -> 2324.0372 | ... P40: =(P10/P25)*1000000 -> 2142.7836
...

Sheet 2026 KPI-大小线（FQC)
C1: 2026 FQC 拒收率-大小线 | T1: 2026 FQC 拒收率-大小线（生产用）
C2: 月份 | D2: 1月 | E2: 2月 | F2: 3月 | G2: 4月 | H2: 5月 | I2: 6月 | J2: 7月 | K2: 8月 | L2: 9月 | M2: 10月 | N2: 11月 | O2: 12月 | P2: YTD | T2: 月份 | U2: 1月 | V2: 2月 | W2: 3月 | X2: 4月 | Y2: 5月 | Z2: 6月 | AA2: 7月 | AB2: 8月 | AC2: 9月 | AD2: 10月 | AE2: 11月 | AF2: 12月 | AG2: YTD
A3: Rejected Qty | B3: 大线 | C3: KID CYCLING | P3: =SUM(D3:O3) -> 0 | R3: Rejected Qty | S3: 大线 | T3: KID CYCLING | AG3: =SUM(U3:AF3) -> 0
C4: 山地ST | D4: 57 | E4: 11 | F4: 78 | G4: 153 | H4: 95 | I4: 43 | P4: =SUM(D4:O4) -> 437 | T4: 山地ST | U4: 48 | V4: 8 | W4: 75 | X4: 151 | Y4: 69 | AG4: =SUM(U4:AF4) -> 351
C5: 山地XC/AM/Race | F5: 2 | H5: 1 | I5: 2 | P5: =SUM(D5:O5) -> 5 | T5: 山地XC/AM/Race | W5: 2 | AG5: =SUM(U5:AF5) -> 2
C6: Hybrid Bike | P6: =SUM(D6:O6) -> 0 | T6: Hybrid Bike | AG6: =SUM(U6:AF6) -> 0
C7: 公路RC | P7: =SUM(D7:O7) -> 0 | T7: 公路RC | AG7: =SUM(U7:AF7) -> 0
C8: 大线GRVL | H8: 20 | I8: 3 | P8: =SUM(D8:O8) -> 23 | T8: 大线GRVL | Y8: 20 | AG8: =SUM(U8:AF8) -> 20
C9: 大线EDR | D9: 2 | E9: 0 | F9: 1 | G9: 0 | H9: 1 | P9: =SUM(D9:O9) -> 4 | T9: 大线EDR | U9: 2 | V9: 0 | W9: 1 | X9: 0 | Y9: 1 | AG9: =SUM(U9:AF9) -> 4
C10: Total | D10: =sum(D3:D9) -> 59 | E10: =sum(E3:E9) -> 11 | F10: =sum(F3:F9) -> 81 | G10: =sum(G3:G9) -> 153 | H10: =sum(H3:H9) -> 117 | I10: =sum(I3:I9) -> 48 | J10: =sum(J3:J9) -> 0 | K10: =sum(K3:K9) -> 0 | ... P10: =sum(P3:P9) -> 469 | T10: Total | U10: =sum(U3:U9) -> 50 | V10: =sum(V3:V9) -> 8 | W10: =sum(W3:W9) -> 78 | X10: =sum(X3:X9) -> 151 | Y10: =sum(Y3:Y9) -> 90 | Z10: =sum(Z3:Z9) -> 0 | AA10: =sum(AA3:AA9) -> 0 | AB10: =sum(AB3:AB9) -> 0 | ... AG10: =sum(AG3:AG9) -> 377
B11: 小线 | C11: 小线GRVL | D11: 0 | E11: 0 | P11: =SUM(D11:O11) -> 0 | S11: 小线 | T11: 小线GRVL | U11: 0 | AG11: =SUM(U11:AF11) -> 0
C12: 小线EDR | P12: =SUM(D12:O12) -> 0 | T12: 小线EDR | AG12: =SUM(U12:AF12) -> 0
C13: 小线RCR | D13: 1 | E13: 0 | F13: 2 | G13: 4 | H13: 1 | O13: 0 | P13: =SUM(D13:O13) -> 8 | T13: 小线RCR | U13: 1 | X13: 7 | Y13: 1 | AG13: =SUM(U13:AF13) -> 9
C14: Touring | D14: 0 | G14: 1 | P14: =SUM(D14:O14) -> 1 | T14: Touring | U14: 0 | X14: 1 | AG14: =SUM(U14:AF14) -> 1
C15: 小线XC | D15: 0 | P15: =SUM(D15:O15) -> 0 | T15: 小线XC | U15: 0 | AG15: =SUM(U15:AF15) -> 0
C16: Carbon Wheel | D16: 0 | E16: 0 | G16: 0 | P16: =SUM(D16:O16) -> 0 | T16: Carbon Wheel | U16: 0 | X16: 0 | AG16: =SUM(U16:AF16) -> 0
C17: Total | D17: =sum(D11:D16) -> 1 | E17: =sum(E11:E16) -> 0 | F17: =sum(F11:F16) -> 2 | G17: =sum(G11:G16) -> 5 | H17: =sum(H11:H16) -> 1 | I17: =sum(I11:I16) -> 0 | J17: =sum(J11:J16) -> 0 | K17: =sum(K11:K16) -> 0 | ... P17: =sum(P11:P16) -> 9 | T17: Total | U17: =SUM(U11:U16) -> 1 | V17: =SUM(V11:V16) -> 0 | W17: =SUM(W11:W16) -> 0 | X17: =SUM(X11:X16) -> 8 | Y17: =SUM(Y11:Y16) -> 1 | Z17: =SUM(Z11:Z16) -> 0 | AA17: =SUM(AA11:AA16) -> 0 | AB17: =SUM(AB11:AB16) -> 0 | ... AG17: =SUM(AG11:AG16) -> 10
B18: Total | C18: 工厂Total | D18: =D10+D17 -> 60 | E18: =E10+E17 -> 11 | F18: =F10+F17 -> 83 | G18: =G10+G17 -> 158 | H18: =H10+H17 -> 118 | I18: =I10+I17 -> 48 | J18: =J10+J17 -> 0 | K18: =K10+K17 -> 0 | ... P18: =P10+P17 -> 478 | S18: Total | T18: 工厂Total | U18: =sum(U3:U9,U11:U16) -> 51 | V18: =sum(V3:V9,V11:V16) -> 8 | W18: =sum(W3:W9,W11:W16) -> 78 | X18: =sum(X3:X9,X11:X16) -> 159 | Y18: =sum(Y3:Y9,Y11:Y16) -> 91 | Z18: =sum(Z3:Z9,Z11:Z16) -> 0 | AA18: =sum(AA3:AA9,AA11:AA16) -> 0 | AB18: =sum(AB3:AB9,AB11:AB16) -> 0 | ... AG18: =sum(AG3:AG9,AG11:AG16) -> 387
A19: Ship out number | B19: 大线 | C19: KID CYCLING | P19: =SUM(D19:O19) -> 0 | R19: Ship out number | S19: 大线 | T19: KID CYCLING | U19: =D19 | V19: =E19 | W19: =F19 | X19: =G19 | Y19: =H19 | Z19: =I19 | AA19: =J19 | AB19: =K19 | ... AF19: =O19 | AG19: =SUM(U19:AF19) -> 0
C20: 山地ST | D20: 8753 | E20: 5000 | F20: 11291 | G20: 13158 | H20: 9928 | I20: 6730 | P20: =SUM(D20:O20) -> 54860 | T20: 山地ST | U20: =D20 -> 8753 | V20: =E20 -> 5000 | W20: =F20 -> 11291 | X20: =G20 -> 13158 | Y20: =H20 -> 9928 | Z20: =I20 -> 6730 | AA20: =J20 | AB20: =K20 | ... AF20: =O20 | AG20: =SUM(U20:AF20) -> 54860
C21: 山地XC/AM/Race | F21: 73 | H21: 21 | I21: 28 | P21: =SUM(D21:O21) -> 122 | T21: 山地XC/AM/Race | U21: =D21 | V21: =E21 | W21: =F21 -> 73 | X21: =G21 | Y21: =H21 -> 21 | Z21: =I21 -> 28 | AA21: =J21 | AB21: =K21 | ... AF21: =O21 | AG21: =SUM(U21:AF21) -> 122
C22: Hybrid Bike | P22: =SUM(D22:O22) -> 0 | T22: Hybrid Bike | U22: =D22 | V22: =E22 | W22: =F22 | X22: =G22 | Y22: =H22 | Z22: =I22 | AA22: =J22 | AB22: =K22 | ... AF22: =O22 | AG22: =SUM(U22:AF22) -> 0
C23: 公路RC | P23: =SUM(D23:O23) -> 0 | T23: 公路RC | U23: =D23 | V23: =E23 | W23: =F23 | X23: =G23 | Y23: =H23 | Z23: =I23 | AA23: =J23 | AB23: =K23 | ... AF23: =O23 | AG23: =SUM(U23:AF23) -> 0
C24: 大线GRVL | H24: 33 | I24: 378 | P24: =SUM(D24:O24) -> 411 | T24: 大线GRVL | U24: =D24 | V24: =E24 | W24: =F24 | X24: =G24 | Y24: =H24 -> 33 | Z24: =I24 -> 378 | AA24: =J24 | AB24: =K24 | ... AF24: =O24 | AG24: =SUM(U24:AF24) -> 411
C25: 大线EDR | D25: 128 | E25: 129 | F25: 163 | G25: 109 | H25: 195 | I25: 297 | P25: =SUM(D25:O25) -> 1021 | T25: 大线EDR | U25: =D25 -> 128 | V25: =E25 -> 129 | W25: =F25 -> 163 | X25: =G25 -> 109 | Y25: =H25 -> 195 | Z25: =I25 -> 297 | AA25: =J25 | AB25: =K25 | ... AF25: =O25 | AG25: =SUM(U25:AF25) -> 1021
C26: Total | D26: =sum(D19:D25) -> 8881 | E26: =sum(E19:E25) -> 5129 | F26: =sum(F19:F25) -> 11527 | G26: =sum(G19:G25) -> 13267 | H26: =sum(H19:H25) -> 10177 | I26: =sum(I19:I25) -> 7433 | J26: =sum(J19:J25) -> 0 | K26: =sum(K19:K25) -> 0 | ... O26: =sum(O19:O25) -> 0 | P26: =sum(D26:O26) -> 56414 | T26: Total | U26: =sum(U19:U25) -> 8881 | V26: =sum(V19:V25) -> 5129 | W26: =sum(W19:W25) -> 11527 | X26: =sum(X19:X25) -> 13267 | Y26: =sum(Y19:Y25) -> 10177 | Z26: =sum(Z19:Z25) -> 7433 | AA26: =sum(AA19:AA25) -> 0 | AB26: =sum(AB19:AB25) -> 0 | ... AF26: =sum(AF19:AF25) -> 0 | AG26: =sum(U26:AF26) -> 56414
B27: 小线 | C27: 小线GRVL | D27: 6 | E27: 18 | P27: =sum(D27:O27) -> 24 | S27: 小线 | T27: 小线GRVL | U27: =D27 -> 6 | V27: =E27 -> 18 | W27: =F27 | X27: =G27 | Y27: =H27 | Z27: =I27 | AA27: =J27 | AB27: =K27 | ... AF27: =O27 | AG27: =sum(U27:AF27) -> 24
C28: 小线EDR | P28: =SUM(D28:O28) -> 0 | T28: 小线EDR | U28: =D28 | V28: =E28 | W28: =F28 | X28: =G28 | Y28: =H28 | Z28: =I28 | AA28: =J28 | AB28: =K28 | ... AF28: =O28 | AG28: =SUM(U28:AF28) -> 0
C29: 小线RCR | D29: 77 | E29: 48 | F29: 156 | G29: 196 | H29: 261 | I29: 440 | P29: =SUM(D29:O29) -> 1178 | T29: 小线RCR | U29: =D29 -> 77 | V29: =E29 -> 48 | W29: =F29 -> 156 | X29: =G29 -> 196 | Y29: =H29 -> 261 | Z29: =I29 -> 440 | AA29: =J29 | AB29: =K29 | ... AF29: =O29 | AG29: =SUM(U29:AF29) -> 1178
C30: Touring | D30: 29 | G30: 17 | P30: =SUM(D30:O30) -> 46 | T30: Touring | U30: =D30 -> 29 | V30: =E30 | W30: =F30 | X30: =G30 -> 17 | Y30: =H30 | Z30: =I30 | AA30: =J30 | AB30: =K30 | ... AF30: =O30 | AG30: =SUM(U30:AF30) -> 46
C31: 小线XC | D31: 4 | H31: 1 | P31: =SUM(D31:O31) -> 5 | T31: 小线XC | U31: =D31 -> 4 | V31: =E31 | W31: =F31 | X31: =G31 | Y31: =H31 -> 1 | Z31: =I31 | AA31: =J31 | AB31: =K31 | ... AF31: =O31 | AG31: =SUM(U31:AF31) -> 5
C32: Carbon Wheel | D32: 116 | E32: 8 | G32: 28 | H32: 126 | I32: 34 | P32: =SUM(D32:O32) -> 312 | T32: Carbon Wheel | U32: =D32 -> 116 | V32: =E32 -> 8 | W32: =F32 | X32: =G32 -> 28 | Y32: =H32 -> 126 | Z32: =I32 -> 34 | AA32: =J32 | AB32: =K32 | ... AF32: =O32 | AG32: =SUM(U32:AF32) -> 312
C33: Total | D33: =sum(D27:D32) -> 232 | E33: =sum(E27:E32) -> 74 | F33: =sum(F27:F32) -> 156 | G33: =sum(G27:G32) -> 241 | H33: =sum(H27:H32) -> 388 | I33: =sum(I27:I32) -> 474 | J33: =sum(J27:J32) -> 0 | K33: =sum(K27:K32) -> 0 | ... P33: =sum(P27:P32) -> 1565 | T33: Total | U33: =sum(U27:U32) -> 232 | V33: =sum(V27:V32) -> 74 | W33: =sum(W27:W32) -> 156 | X33: =sum(X27:X32) -> 241 | Y33: =sum(Y27:Y32) -> 388 | Z33: =sum(Z27:Z32) -> 474 | AA33: =sum(AA27:AA32) -> 0 | AB33: =sum(AB27:AB32) -> 0 | ... AG33: =sum(AG27:AG32) -> 1565
B34: Total | C34: 工厂Total | D34: =D26+D33 -> 9113 | E34: =E26+E33 -> 5203 | F34: =F26+F33 -> 11683 | G34: =G26+G33 -> 13508 | H34: =H26+H33 -> 10565 | I34: =I26+I33 -> 7907 | J34: =J26+J33 -> 0 | K34: =K26+K33 -> 0 | ... P34: =P26+P33 -> 57979 | S34: Total | T34: 工厂Total | U34: =sum(U19:U25,U27:U32) -> 9113 | V34: =sum(V19:V25,V27:V32) -> 5203 | W34: =sum(W19:W25,W27:W32) -> 11683 | X34: =sum(X19:X25,X27:X32) -> 13508 | Y34: =sum(Y19:Y25,Y27:Y32) -> 10565 | Z34: =sum(Z19:Z25,Z27:Z32) -> 7907 | AA34: =sum(AA19:AA25,AA27:AA32) -> 0 | AB34: =sum(AB19:AB25,AB27:AB32) -> 0 | ... AG34: =sum(AG19:AG25,AG27:AG32) -> 57979
A35: PPM | B35: 大线 | C35: KID CYCLING | D35: =(D3/D19)*1000000 -> #DIV/0! | E35: =(E3/E19)*1000000 -> #DIV/0! | F35: =(F3/F19)*1000000 -> #DIV/0! | G35: =(G3/G19)*1000000 -> #DIV/0! | H35: =(H3/H19)*1000000 -> #DIV/0! | I35: =(I3/I19)*1000000 -> #DIV/0! | J35: =(J3/J19)*1000000 -> #DIV/0! | K35: =(K3/K19)*1000000 -> #DIV/0! | ... P35: =(P3/P19)*1000000 -> #DIV/0! | R35: DPPM | S35: 大线 | T35: KID CYCLING | U35: =(U3/U19)*1000000 -> #DIV/0! | V35: =(V3/V19)*1000000 -> #DIV/0! | W35: =(W3/W19)*1000000 -> #DIV/0! | X35: =(X3/X19)*1000000 -> #DIV/0! | Y35: =(Y3/Y19)*1000000 -> #DIV/0! | Z35: =(Z3/Z19)*1000000 -> #DIV/0! | AA35: =(AA3/AA19)*1000000 -> #DIV/0! | AB35: =(AB3/AB19)*1000000 -> #DIV/0! | ... AG35: =(AG3/AG19)*1000000 -> #DIV/0!
C36: 山地ST | D36: =(D4/D20)*1000000 -> 6512.053 | E36: =(E4/E20)*1000000 -> 2200 | F36: =(F4/F20)*1000000 -> 6908.1569 | G36: =(G4/G20)*1000000 -> 11627.907 | H36: =(H4/H20)*1000000 -> 9568.8961 | I36: =(I4/I20)*1000000 -> 6389.3016 | J36: =(J4/J20)*1000000 -> #DIV/0! | K36: =(K4/K20)*1000000 -> #DIV/0! | ... P36: =(P4/P20)*1000000 -> 7965.731 | T36: 山地ST | U36: =(U4/U20)*1000000 -> 5483.8341 | V36: =(V4/V20)*1000000 -> 1600 | W36: =(W4/W20)*1000000 -> 6642.4586 | X36: =(X4/X20)*1000000 -> 11475.908 | Y36: =(Y4/Y20)*1000000 -> 6950.0403 | Z36: =(Z4/Z20)*1000000 -> 0 | AA36: =(AA4/AA20)*1000000 -> #DIV/0! | AB36: =(AB4/AB20)*1000000 -> #DIV/0! | ... AG36: =(AG4/AG20)*1000000 -> 6398.1043
C37: 山地XC/AM/Race | D37: =(D5/D21)*1000000 -> #DIV/0! | E37: =(E5/E21)*1000000 -> #DIV/0! | F37: =(F5/F21)*1000000 -> 27397.26 | G37: =(G5/G21)*1000000 -> #DIV/0! | H37: =(H5/H21)*1000000 -> 47619.048 | I37: =(I5/I21)*1000000 -> 71428.571 | J37: =(J5/J21)*1000000 -> #DIV/0! | K37: =(K5/K21)*1000000 -> #DIV/0! | ... P37: =(P5/P21)*1000000 -> 40983.607 | T37: 山地XC/AM/Race | U37: =(U5/U21)*1000000 -> #DIV/0! | V37: =(V5/V21)*1000000 -> #DIV/0! | W37: =(W5/W21)*1000000 -> 27397.26 | X37: =(X5/X21)*1000000 -> #DIV/0! | Y37: =(Y5/Y21)*1000000 -> 0 | Z37: =(Z5/Z21)*1000000 -> 0 | AA37: =(AA5/AA21)*1000000 -> #DIV/0! | AB37: =(AB5/AB21)*1000000 -> #DIV/0! | ... AG37: =(AG5/AG21)*1000000 -> 16393.443
C38: Hybrid Bike | D38: =(D6/D22)*1000000 -> #DIV/0! | E38: =(E6/E22)*1000000 -> #DIV/0! | F38: =(F6/F22)*1000000 -> #DIV/0! | G38: =(G6/G22)*1000000 -> #DIV/0! | H38: =(H6/H22)*1000000 -> #DIV/0! | I38: =(I6/I22)*1000000 -> #DIV/0! | J38: =(J6/J22)*1000000 -> #DIV/0! | K38: =(K6/K22)*1000000 -> #DIV/0! | ... P38: =(P6/P22)*1000000 -> #DIV/0! | T38: Hybrid Bike | U38: =(U6/U22)*1000000 -> #DIV/0! | V38: =(V6/V22)*1000000 -> #DIV/0! | W38: =(W6/W22)*1000000 -> #DIV/0! | X38: =(X6/X22)*1000000 -> #DIV/0! | Y38: =(Y6/Y22)*1000000 -> #DIV/0! | Z38: =(Z6/Z22)*1000000 -> #DIV/0! | AA38: =(AA6/AA22)*1000000 -> #DIV/0! | AB38: =(AB6/AB22)*1000000 -> #DIV/0! | ... AG38: =(AG6/AG22)*1000000 -> #DIV/0!
C39: 公路RC | D39: =(D7/D23)*1000000 -> #DIV/0! | E39: =(E7/E23)*1000000 -> #DIV/0! | F39: =(F7/F23)*1000000 -> #DIV/0! | G39: =(G7/G23)*1000000 -> #DIV/0! | H39: =(H7/H23)*1000000 -> #DIV/0! | I39: =(I7/I23)*1000000 -> #DIV/0! | J39: =(J7/J23)*1000000 -> #DIV/0! | K39: =(K7/K23)*1000000 -> #DIV/0! | ... P39: =(P7/P23)*1000000 -> #DIV/0! | T39: 公路RC | U39: =(U7/U23)*1000000 -> #DIV/0! | V39: =(V7/V23)*1000000 -> #DIV/0! | W39: =(W7/W23)*1000000 -> #DIV/0! | X39: =(X7/X23)*1000000 -> #DIV/0! | Y39: =(Y7/Y23)*1000000 -> #DIV/0! | Z39: =(Z7/Z23)*1000000 -> #DIV/0! | AA39: =(AA7/AA23)*1000000 -> #DIV/0! | AB39: =(AB7/AB23)*1000000 -> #DIV/0! | ... AG39: =(AG7/AG23)*1000000 -> #DIV/0!
C40: 大线GRVL | D40: =(D8/D24)*1000000 -> #DIV/0! | E40: =(E8/E24)*1000000 -> #DIV/0! | F40: =(F8/F24)*1000000 -> #DIV/0! | G40: =(G8/G24)*1000000 -> #DIV/0! | H40: =(H8/H24)*1000000 -> 606060.61 | I40: =(I8/I24)*1000000 -> 7936.5079 | J40: =(J8/J24)*1000000 -> #DIV/0! | K40: =(K8/K24)*1000000 -> #DIV/0! | ... P40: =(P8/P24)*1000000 -> 55961.071 | T40: 大线GRVL | U40: =(U8/U24)*1000000 -> #DIV/0! | V40: =(V8/V24)*1000000 -> #DIV/0! | W40: =(W8/W24)*1000000 -> #DIV/0! | X40: =(X8/X24)*1000000 -> #DIV/0! | Y40: =(Y8/Y24)*1000000 -> 606060.61 | Z40: =(Z8/Z24)*1000000 -> 0 | AA40: =(AA8/AA24)*1000000 -> #DIV/0! | AB40: =(AB8/AB24)*1000000 -> #DIV/0! | ... AG40: =(AG8/AG24)*1000000 -> 48661.8
...

Sheet 2024 KPI-大小线（FQC)
C1: 2024 FQC 拒收率-大小线 | T1: 2024 FQC 拒收率-大小线（生产用）
C2: 月份 | D2: 1月 | E2: 2月 | F2: 3月 | G2: 4月 | H2: 5月 | I2: 6月 | J2: 7月 | K2: 8月 | L2: 9月 | M2: 10月 | N2: 11月 | O2: 12月 | P2: YTD | T2: 月份 | U2: 1月 | V2: 2月 | W2: 3月 | X2: 4月 | Y2: 5月 | Z2: 6月 | AA2: 7月 | AB2: 8月 | AC2: 9月 | AD2: 10月 | AE2: 11月 | AF2: 12月 | AG2: YTD
A3: Rejected Qty | B3: 大线 | C3: KID CYCLING | D3: 1 | E3: 0 | F3: 0 | J3: 1 | K3: 1 | L3: 2 | M3: 1 | O3: 0 | P3: =SUM(D3:O3) -> 6 | R3: Rejected Qty | S3: 大线 | T3: KID CYCLING | U3: 0 | V3: 0 | W3: 0 | AA3: 1 | AB3: 1 | AC3: 2 | AD3: 1 | AF3: 0 | AG3: =SUM(U3:AF3) -> 5
C4: 山地ST | D4: 92 | E4: 11 | F4: 19 | G4: 35 | H4: 4 | I4: 4 | J4: 8 | K4: 11 | L4: 7 | M4: 2 | N4: 1 | O4: 14 | P4: =SUM(D4:O4) -> 208 | T4: 山地ST | U4: 91 | V4: 5 | W4: 19 | X4: 34 | Y4: 2 | Z4: 3 | AA4: 7 | AB4: 10 | AC4: 7 | AD4: 2 | AE4: 1 | AF4: 13 | AG4: =SUM(U4:AF4) -> 194
C5: 山地XC/AM/Race | D5: 5 | E5: 0 | F5: 1 | G5: 0 | H5: 1 | I5: 0 | J5: 7 | K5: 2 | L5: 19 | M5: 10 | N5: 1 | O5: 0 | P5: =SUM(D5:O5) -> 46 | T5: 山地XC/AM/Race | U5: 2 | V5: 0 | W5: 1 | X5: 0 | Y5: 1 | AA5: 7 | AB5: 2 | AC5: 3 | AD5: 10 | AE5: 1 | AF5: 0 | AG5: =SUM(U5:AF5) -> 27
C6: Hybrid Bike | D6: 1 | E6: 0 | F6: 1 | I6: 24 | K6: 14 | L6: 1 | M6: 1 | O6: 0 | P6: =SUM(D6:O6) -> 42 | T6: Hybrid Bike | U6: 1 | V6: 0 | W6: 1 | Z6: 24 | AB6: 14 | AC6: 1 | AD6: 1 | AF6: 0 | AG6: =SUM(U6:AF6) -> 42
C7: 公路RC | D7: 8 | E7: 2 | F7: 3 | G7: 4 | H7: 5 | I7: 5 | J7: 2 | K7: 4 | L7: 1 | M7: 2 | N7: 2 | O7: 4 | P7: =SUM(D7:O7) -> 42 | T7: 公路RC | U7: 6 | V7: 1 | W7: 3 | X7: 4 | Y7: 4 | Z7: 5 | AA7: 2 | AB7: 4 | AC7: 1 | AD7: 2 | AE7: 2 | AF7: 3 | AG7: =SUM(U7:AF7) -> 37
C8: 大线GRVL | E8: 1 | F8: 1 | G8: 1 | H8: 2 | I8: 13 | J8: 1 | K8: 0 | M8: 2 | O8: 14 | P8: =SUM(D8:O8) -> 35 | T8: 大线GRVL | V8: 1 | W8: 1 | X8: 1 | Y8: 2 | Z8: 12 | AA8: 1 | AD8: 2 | AF8: 14 | AG8: =SUM(U8:AF8) -> 34
C9: 大线EDR | D9: 2 | E9: 27 | F9: 1 | G9: 36 | H9: 1 | I9: 0 | J9: 1 | K9: 2 | L9: 2 | M9: 0 | O9: 1 | P9: =SUM(D9:O9) -> 73 | T9: 大线EDR | U9: 2 | V9: 18 | W9: 1 | X9: 36 | Y9: 0 | AB9: 2 | AC9: 1 | AD9: 0 | AF9: 1 | AG9: =SUM(U9:AF9) -> 61
C10: Total | D10: =sum(D3:D9) -> 109 | E10: =sum(E3:E9) -> 41 | F10: =sum(F3:F9) -> 26 | G10: =sum(G3:G9) -> 76 | H10: =sum(H3:H9) -> 13 | I10: =sum(I3:I9) -> 46 | J10: =sum(J3:J9) -> 20 | K10: =sum(K3:K9) -> 34 | ... P10: =sum(P3:P9) -> 452 | T10: Total | U10: =sum(U3:U9) -> 102 | V10: =sum(V3:V9) -> 25 | W10: =sum(W3:W9) -> 26 | X10: =sum(X3:X9) -> 75 | Y10: =sum(Y3:Y9) -> 9 | Z10: =sum(Z3:Z9) -> 44 | AA10: =sum(AA3:AA9) -> 18 | AB10: =sum(AB3:AB9) -> 33 | ... AG10: =sum(AG3:AG9) -> 400
B11: 小线 | C11: 小线GRVL | D11: 0 | E11: 4 | F11: 3 | G11: 4 | H11: 3 | I11: 0 | J11: 3 | K11: 0 | L11: 0 | O11: 1 | P11: =SUM(D11:O11) -> 18 | S11: 小线 | T11: 小线GRVL | U11: 0 | V11: 4 | W11: 2 | X11: 4 | Y11: 2 | AA11: 3 | AC11: 0 | AF11: 1 | AG11: =SUM(U11:AF11) -> 16
C12: 小线EDR | D12: 1 | E12: 2 | F12: 2 | G12: 8 | H12: 2 | I12: 2 | J12: 1 | K12: 1 | L12: 1 | M12: 0 | O12: 0 | P12: =SUM(D12:O12) -> 20 | T12: 小线EDR | U12: 0 | V12: 1 | W12: 1 | X12: 7 | Y12: 1 | Z12: 2 | AA12: 1 | AB12: 1 | AC12: 1 | AD12: 0 | AF12: 0 | AG12: =SUM(U12:AF12) -> 15
C13: 小线RCR | D13: 1 | E13: 1 | F13: 0 | G13: 1 | H13: 1 | I13: 1 | J13: 5 | K13: 5 | L13: 2 | M13: 4 | O13: 1 | P13: =SUM(D13:O13) -> 22 | T13: 小线RCR | U13: 1 | V13: 1 | W13: 0 | X13: 1 | Y13: 1 | Z13: 1 | AA13: 5 | AB13: 5 | AC13: 2 | AG13: =SUM(U13:AF13) -> 17
C14: Touring | E14: 0 | G14: 45 | J14: 1 | K14: 1 | P14: =SUM(D14:O14) -> 47 | T14: Touring | V14: 0 | X14: 45 | AA14: 1 | AB14: 1 | AG14: =SUM(U14:AF14) -> 47
C15: 小线XC | G15: 0 | K15: 0 | L15: 0 | M15: 1 | N15: 2 | P15: =SUM(D15:O15) -> 3 | T15: 小线XC | X15: 0 | AC15: 0 | AD15: 1 | AE15: 1 | AG15: =SUM(U15:AF15) -> 2
C16: Total | D16: =SUM(D11:D14) -> 2 | E16: =SUM(E11:E14) -> 7 | F16: =SUM(F11:F14) -> 5 | G16: =SUM(G11:G15) -> 58 | H16: =SUM(H11:H14) -> 6 | I16: =SUM(I11:I14) -> 3 | J16: =SUM(J11:J14) -> 10 | K16: =SUM(K11:K15) -> 7 | L16: =SUM(L11:L15) -> 3 | M16: =SUM(M11:M15) -> 5 | N16: =SUM(N11:N15) -> 2 | O16: =SUM(O11:O14) -> 2 | P16: =SUM(D16:O16) -> 110 | T16: Total | U16: =SUM(U11:U14) -> 1 | V16: =SUM(V11:V14) -> 6 | W16: =SUM(W11:W14) -> 3 | X16: =SUM(X11:X15) -> 57 | Y16: =SUM(Y11:Y14) -> 4 | Z16: =SUM(Z11:Z14) -> 3 | AA16: =SUM(AA11:AA14) -> 10 | AB16: =SUM(AB11:AB14) -> 7 | AC16: =SUM(AC11:AC15) -> 3 | AD16: =SUM(AD11:AD15) -> 1 | AE16: =SUM(AE11:AE15) -> 1 | AF16: =SUM(AF11:AF14) -> 1 | AG16: =SUM(U16:AF16) -> 97
B17: Total | C17: 工厂Total | D17: =sum(D3:D9,D11:D15) -> 111 | E17: =sum(E3:E9,E11:E15) -> 48 | F17: =sum(F3:F9,F11:F15) -> 31 | G17: =sum(G3:G9,G11:G15) -> 134 | H17: =sum(H3:H9,H11:H15) -> 19 | I17: =sum(I3:I9,I11:I15) -> 49 | J17: =sum(J3:J9,J11:J15) -> 30 | K17: =sum(K3:K9,K11:K15) -> 41 | ... P17: =sum(P3:P9,P11:P15) -> 562 | S17: Total | T17: 工厂Total | U17: =sum(U3:U9,U11:U15) -> 103 | V17: =sum(V3:V9,V11:V15) -> 31 | W17: =sum(W3:W9,W11:W15) -> 29 | X17: =sum(X3:X9,X11:X15) -> 132 | Y17: =sum(Y3:Y9,Y11:Y15) -> 13 | Z17: =sum(Z3:Z9,Z11:Z15) -> 47 | AA17: =sum(AA3:AA9,AA11:AA15) -> 28 | AB17: =sum(AB3:AB9,AB11:AB15) -> 40 | ... AG17: =sum(AG3:AG9,AG11:AG15) -> 497
A18: Ship out number | B18: 大线 | C18: KID CYCLING | D18: 24 | J18: 72 | K18: 48 | L18: 96 | M18: 120 | N18: 24 | P18: =SUM(D18:O18) -> 384 | R18: Ship out number | S18: 大线 | T18: KID CYCLING | U18: =D18 -> 24 | V18: =E18 | W18: =F18 | X18: =G18 | Y18: =H18 | Z18: =I18 | AA18: =J18 -> 72 | AB18: =K18 -> 48 | ... AF18: =O18 | AG18: =SUM(U18:AF18) -> 384
C19: 山地ST | D19: 2118 | E19: 1696 | F19: 2576 | G19: 2641 | H19: 3492 | I19: 4107 | J19: 2744 | K19: 4079 | L19: 3060 | M19: 828 | N19: 306 | O19: 993 | P19: =SUM(D19:O19) -> 28640 | T19: 山地ST | U19: =D19 -> 2118 | V19: =E19 -> 1696 | W19: =F19 -> 2576 | X19: =G19 -> 2641 | Y19: =H19 -> 3492 | Z19: =I19 -> 4107 | AA19: =J19 -> 2744 | AB19: =K19 -> 4079 | ... AF19: =O19 -> 993 | AG19: =SUM(U19:AF19) -> 28640
C20: 山地XC/AM/Race | D20: 12 | E20: 16 | F20: 32 | G20: 16 | H20: 108 | I20: 52 | J20: 8 | K20: 44 | L20: 120 | M20: 27 | N20: 70 | O20: 7 | P20: =SUM(D20:O20) -> 512 | T20: 山地XC/AM/Race | U20: =D20 -> 12 | V20: =E20 -> 16 | W20: =F20 -> 32 | X20: =G20 -> 16 | Y20: =H20 -> 108 | Z20: =I20 -> 52 | AA20: =J20 -> 8 | AB20: =K20 -> 44 | ... AF20: =O20 -> 7 | AG20: =SUM(U20:AF20) -> 512
C21: Hybrid Bike | D21: 90 | E21: 16 | F21: 80 | I21: 80 | K21: 68 | L21: 112 | M21: 136 | N21: 15 | P21: =SUM(D21:O21) -> 597 | T21: Hybrid Bike | U21: =D21 -> 90 | V21: =E21 -> 16 | W21: =F21 -> 80 | X21: =G21 | Y21: =H21 | Z21: =I21 -> 80 | AA21: =J21 | AB21: =K21 -> 68 | ... AF21: =O21 | AG21: =SUM(U21:AF21) -> 597
C22: 公路RC | D22: 2563 | E22: 253 | F22: 381 | G22: 1374 | H22: 1758 | I22: 2062 | J22: 1475 | K22: 962 | L22: 650 | M22: 560 | N22: 505 | O22: 866 | P22: =SUM(D22:O22) -> 13409 | T22: 公路RC | U22: =D22 -> 2563 | V22: =E22 -> 253 | W22: =F22 -> 381 | X22: =G22 -> 1374 | Y22: =H22 -> 1758 | Z22: =I22 -> 2062 | AA22: =J22 -> 1475 | AB22: =K22 -> 962 | ... AF22: =O22 -> 866 | AG22: =SUM(U22:AF22) -> 13409
C23: 大线GRVL | E23: 115 | F23: 100 | G23: 118 | H23: 278 | I23: 405 | J23: 94 | K23: 144 | M23: 193 | O23: 395 | P23: =SUM(D23:O23) -> 1842 | T23: 大线GRVL | U23: =D23 | V23: =E23 -> 115 | W23: =F23 -> 100 | X23: =G23 -> 118 | Y23: =H23 -> 278 | Z23: =I23 -> 405 | AA23: =J23 -> 94 | AB23: =K23 -> 144 | ... AF23: =O23 -> 395 | AG23: =SUM(U23:AF23) -> 1842
C24: 大线EDR | D24: 631 | E24: 426 | F24: 764 | G24: 471 | H24: 1109 | I24: 37 | J24: 446 | K24: 358 | L24: 751 | M24: 330 | O24: 192 | P24: =SUM(D24:O24) -> 5515 | T24: 大线EDR | U24: =D24 -> 631 | V24: =E24 -> 426 | W24: =F24 -> 764 | X24: =G24 -> 471 | Y24: =H24 -> 1109 | Z24: =I24 -> 37 | AA24: =J24 -> 446 | AB24: =K24 -> 358 | ... AF24: =O24 -> 192 | AG24: =SUM(U24:AF24) -> 5515
C25: Total | D25: =sum(D18:D24) -> 5438 | E25: =sum(E18:E24) -> 2522 | F25: =sum(F18:F24) -> 3933 | G25: =sum(G18:G24) -> 4620 | H25: =sum(H18:H24) -> 6745 | I25: =sum(I18:I24) -> 6743 | J25: =sum(J18:J24) -> 4839 | K25: =sum(K18:K24) -> 5703 | ... O25: =sum(O18:O24) -> 2453 | P25: =sum(D25:O25) -> 50899 | T25: Total | U25: =sum(U18:U24) -> 5438 | V25: =sum(V18:V24) -> 2522 | W25: =sum(W18:W24) -> 3933 | X25: =sum(X18:X24) -> 4620 | Y25: =sum(Y18:Y24) -> 6745 | Z25: =sum(Z18:Z24) -> 6743 | AA25: =sum(AA18:AA24) -> 4839 | AB25: =sum(AB18:AB24) -> 5703 | ... AF25: =sum(AF18:AF24) -> 2453 | AG25: =sum(U25:AF25) -> 50899
B26: 小线 | C26: 小线GRVL | D26: 47 | E26: 210 | F26: 158 | G26: 238 | H26: 229 | I26: 216 | J26: 157 | K26: 224 | L26: 47 | O26: 61 | P26: =sum(D26:O26) -> 1587 | S26: 小线 | T26: 小线GRVL | U26: =D26 -> 47 | V26: =E26 -> 210 | W26: =F26 -> 158 | X26: =G26 -> 238 | Y26: =H26 -> 229 | Z26: =I26 -> 216 | AA26: =J26 -> 157 | AB26: =K26 -> 224 | ... AF26: =O26 -> 61 | AG26: =sum(U26:AF26) -> 1587
C27: 小线EDR | D27: 139 | E27: 121 | F27: 124 | G27: 568 | H27: 129 | I27: 114 | J27: 225 | K27: 66 | L27: 91 | M27: 66 | O27: 185 | P27: =SUM(D27:O27) -> 1828 | T27: 小线EDR | U27: =D27 -> 139 | V27: =E27 -> 121 | W27: =F27 -> 124 | X27: =G27 -> 568 | Y27: =H27 -> 129 | Z27: =I27 -> 114 | AA27: =J27 -> 225 | AB27: =K27 -> 66 | ... AF27: =O27 -> 185 | AG27: =SUM(U27:AF27) -> 1828
C28: 小线RCR | D28: 80 | E28: 57 | F28: 10 | G28: 103 | H28: 128 | I28: 75 | J28: 170 | K28: 233 | L28: 232 | M28: 207 | N28: 73 | O28: 31 | P28: =SUM(D28:O28) -> 1399 | T28: 小线RCR | U28: =D28 -> 80 | V28: =E28 -> 57 | W28: =F28 -> 10 | X28: =G28 -> 103 | Y28: =H28 -> 128 | Z28: =I28 -> 75 | AA28: =J28 -> 170 | AB28: =K28 -> 233 | ... AF28: =O28 -> 31 | AG28: =SUM(U28:AF28) -> 1399
C29: Touring | E29: 47 | G29: 50 | J29: 48 | K29: 54 | P29: =SUM(D29:O29) -> 199 | T29: Touring | U29: =D29 | V29: =E29 -> 47 | W29: =F29 | X29: =G29 -> 50 | Y29: =H29 | Z29: =I29 | AA29: =J29 -> 48 | AB29: =K29 -> 54 | ... AF29: =O29 | AG29: =SUM(U29:AF29) -> 199
C30: 小线XC | G30: 54 | K30: 14 | L30: 67 | M30: 3 | N30: 64 | P30: =SUM(D30:O30) -> 202 | T30: 小线XC | U30: =D30 | V30: =E30 | W30: =F30 | X30: =G30 -> 54 | Y30: =H30 | Z30: =I30 | AA30: =J30 | AB30: =K30 -> 14 | ... AF30: =O30 | AG30: =SUM(U30:AF30) -> 202
C31: Total | D31: =sum(D26:D30) -> 266 | E31: =sum(E26:E30) -> 435 | F31: =sum(F26:F30) -> 292 | G31: =sum(G26:G30) -> 1013 | H31: =sum(H26:H30) -> 486 | I31: =sum(I26:I30) -> 405 | J31: =sum(J26:J30) -> 600 | K31: =sum(K26:K30) -> 591 | ... P31: =sum(P26:P30) -> 5215 | T31: Total | U31: =sum(U26:U30) -> 266 | V31: =sum(V26:V30) -> 435 | W31: =sum(W26:W30) -> 292 | X31: =sum(X26:X30) -> 1013 | Y31: =sum(Y26:Y30) -> 486 | Z31: =sum(Z26:Z30) -> 405 | AA31: =sum(AA26:AA30) -> 600 | AB31: =sum(AB26:AB30) -> 591 | ... AG31: =sum(AG26:AG30) -> 5215
B32: Total | C32: 工厂Total | D32: =sum(D18:D24,D26:D30) -> 5704 | E32: =sum(E18:E24,E26:E30) -> 2957 | F32: =sum(F18:F24,F26:F30) -> 4225 | G32: =sum(G18:G24,G26:G30) -> 5633 | H32: =sum(H18:H24,H26:H30) -> 7231 | I32: =sum(I18:I24,I26:I30) -> 7148 | J32: =sum(J18:J24,J26:J30) -> 5439 | K32: =sum(K18:K24,K26:K30) -> 6294 | ... P32: =sum(P18:P24,P26:P30) -> 56114 | S32: Total | T32: 工厂Total | U32: =sum(U18:U24,U26:U30) -> 5704 | V32: =sum(V18:V24,V26:V30) -> 2957 | W32: =sum(W18:W24,W26:W30) -> 4225 | X32: =sum(X18:X24,X26:X30) -> 5633 | Y32: =sum(Y18:Y24,Y26:Y30) -> 7231 | Z32: =sum(Z18:Z24,Z26:Z30) -> 7148 | AA32: =sum(AA18:AA24,AA26:AA30) -> 5439 | AB32: =sum(AB18:AB24,AB26:AB30) -> 6294 | ... AG32: =sum(AG18:AG24,AG26:AG30) -> 56114
A33: PPM | B33: 大线 | C33: KID CYCLING | D33: =(D3/D18)*1000000 -> 41666.667 | E33: =(E3/E18)*1000000 -> #DIV/0! | F33: =(F3/F18)*1000000 -> #DIV/0! | G33: =(G3/G18)*1000000 -> #DIV/0! | H33: =(H3/H18)*1000000 -> #DIV/0! | I33: =(I3/I18)*1000000 -> #DIV/0! | J33: =(J3/J18)*1000000 -> 13888.889 | K33: =(K3/K18)*1000000 -> 20833.333 | ... P33: =(P3/P18)*1000000 -> 15625 | R33: DPPM | S33: 大线 | T33: KID CYCLING | U33: =(U3/U18)*1000000 -> 0 | V33: =(V3/V18)*1000000 -> #DIV/0! | W33: =(W3/W18)*1000000 -> #DIV/0! | X33: =(X3/X18)*1000000 -> #DIV/0! | Y33: =(Y3/Y18)*1000000 -> #DIV/0! | Z33: =(Z3/Z18)*1000000 -> #DIV/0! | AA33: =(AA3/AA18)*1000000 -> 13888.889 | AB33: =(AB3/AB18)*1000000 -> 20833.333 | ... AG33: =(AG3/AG18)*1000000 -> 13020.833
C34: 山地ST | D34: =(D4/D19)*1000000 -> 43437.205 | E34: =(E4/E19)*1000000 -> 6485.8491 | F34: =(F4/F19)*1000000 -> 7375.7764 | G34: =(G4/G19)*1000000 -> 13252.556 | H34: =(H4/H19)*1000000 -> 1145.4754 | I34: =(I4/I19)*1000000 -> 973.94692 | J34: =(J4/J19)*1000000 -> 2915.4519 | K34: =(K4/K19)*1000000 -> 2696.7394 | ... P34: =(P4/P19)*1000000 -> 7262.5698 | T34: 山地ST | U34: =(U4/U19)*1000000 -> 42965.061 | V34: =(V4/V19)*1000000 -> 2948.1132 | W34: =(W4/W19)*1000000 -> 7375.7764 | X34: =(X4/X19)*1000000 -> 12873.911 | Y34: =(Y4/Y19)*1000000 -> 572.73769 | Z34: =(Z4/Z19)*1000000 -> 730.46019 | AA34: =(AA4/AA19)*1000000 -> 2551.0204 | AB34: =(AB4/AB19)*1000000 -> 2451.5813 | ... AG34: =(AG4/AG19)*1000000 -> 6773.743
C35: 山地XC/AM/Race | D35: =(D5/D20)*1000000 -> 416666.67 | E35: =(E5/E20)*1000000 -> 0 | F35: =(F5/F20)*1000000 -> 31250 | G35: =(G5/G20)*1000000 -> 0 | H35: =(H5/H20)*1000000 -> 9259.2593 | I35: =(I5/I20)*1000000 -> 0 | J35: =(J5/J20)*1000000 -> 875000 | K35: =(K5/K20)*1000000 -> 45454.545 | ... P35: =(P5/P20)*1000000 -> 89843.75 | T35: 山地XC/AM/Race | U35: =(U5/U20)*1000000 -> 166666.67 | V35: =(V5/V20)*1000000 -> 0 | W35: =(W5/W20)*1000000 -> 31250 | X35: =(X5/X20)*1000000 -> 0 | Y35: =(Y5/Y20)*1000000 -> 9259.2593 | Z35: =(Z5/Z20)*1000000 -> 0 | AA35: =(AA5/AA20)*1000000 -> 875000 | AB35: =(AB5/AB20)*1000000 -> 45454.545 | ... AG35: =(AG5/AG20)*1000000 -> 52734.375
C36: Hybrid Bike | D36: =(D6/D21)*1000000 -> 11111.111 | E36: =(E6/E21)*1000000 -> 0 | F36: =(F6/F21)*1000000 -> 12500 | G36: =(G6/G21)*1000000 -> #DIV/0! | H36: =(H6/H21)*1000000 -> #DIV/0! | I36: =(I6/I21)*1000000 -> 300000 | J36: =(J6/J21)*1000000 -> #DIV/0! | K36: =(K6/K21)*1000000 -> 205882.35 | ... P36: =(P6/P21)*1000000 -> 70351.759 | T36: Hybrid Bike | U36: =(U6/U21)*1000000 -> 11111.111 | V36: =(V6/V21)*1000000 -> 0 | W36: =(W6/W21)*1000000 -> 12500 | X36: =(X6/X21)*1000000 -> #DIV/0! | Y36: =(Y6/Y21)*1000000 -> #DIV/0! | Z36: =(Z6/Z21)*1000000 -> 300000 | AA36: =(AA6/AA21)*1000000 -> #DIV/0! | AB36: =(AB6/AB21)*1000000 -> 205882.35 | ... AG36: =(AG6/AG21)*1000000 -> 70351.759
C37: 公路RC | D37: =(D7/D22)*1000000 -> 3121.3422 | E37: =(E7/E22)*1000000 -> 7905.1383 | F37: =(F7/F22)*1000000 -> 7874.0157 | G37: =(G7/G22)*1000000 -> 2911.2082 | H37: =(H7/H22)*1000000 -> 2844.1411 | I37: =(I7/I22)*1000000 -> 2424.8303 | J37: =(J7/J22)*1000000 -> 1355.9322 | K37: =(K7/K22)*1000000 -> 4158.0042 | ... P37: =(P7/P22)*1000000 -> 3132.2246 | T37: 公路RC | U37: =(U7/U22)*1000000 -> 2341.0066 | V37: =(V7/V22)*1000000 -> 3952.5692 | W37: =(W7/W22)*1000000 -> 7874.0157 | X37: =(X7/X22)*1000000 -> 2911.2082 | Y37: =(Y7/Y22)*1000000 -> 2275.3129 | Z37: =(Z7/Z22)*1000000 -> 2424.8303 | AA37: =(AA7/AA22)*1000000 -> 1355.9322 | AB37: =(AB7/AB22)*1000000 -> 4158.0042 | ... AG37: =(AG7/AG22)*1000000 -> 2759.3407
